<?xml version="1.0" encoding="UTF-8"?>
<!DOCTYPE html >
<html xmlns="http://www.w3.org/1999/xhtml">
<head>
    <title>Reporte de pruebas</title>
    <meta name="generator" content="HTMLTestRunner 0.8.2.1"/>
    <meta http-equiv="Content-Type" content="text/html; charset=UTF-8"/>
    <link href="https://libs.baidu.com/bootstrap/3.0.3/css/bootstrap.min.css" rel="stylesheet">
    <script src="https://libs.baidu.com/jquery/2.0.0/jquery.min.js"></script>
    <script src="https://libs.baidu.com/bootstrap/3.0.3/js/bootstrap.min.js"></script>
    
<style type="text/css" media="screen">
@import url("https://fonts.googleapis.com/css2?family=Poppins:wght@400;500;600&display=swap");
    :root{
        --body-font: 'Poppins', sans-serif;

    }
    body{
        margin: var(--header-height) 0 0 0;
        padding: 1rem 1rem 0;
        font-family: var(--body-font);
        background-color: #F9F6FD;
    }    
    .container{
        background-color: white;
        border-radius: 3%;
    }
    .imagenpwst img{
        position:static;
        right: 4%;
        padding-top: 5%;
    }

/* -- report ------------------------------------------------------------------------ */
#total_row  { font-weight: bold; }
.passCase   { color: #5cb85c; }
.failCase   { color: #d9534f; font-weight: bold; }
.errorCase  { color: #f0ad4e; font-weight: bold; }
.hiddenRow  { display: none; }
.testcase   { margin-left: 2em; }
</style>

</head>
<body >
<div class="imagenpwst">
    <img src="https://i.postimg.cc/g2fdS2VC/Recurso-jpg.jpg"width="320"  align="right" >
</div>    
<script language="javascript" type="text/javascript">
output_list = Array();
/*level 
0:Summary //all hiddenRow
1:Failed  //pt hiddenRow, ft none
2:Pass    //pt none, ft hiddenRow
3:All     //pt none, ft none
4:Error  
*/
function showCase(level) {
    trs = document.getElementsByTagName("tr");
    for (var i = 0; i < trs.length; i++) {
        tr = trs[i];
        id = tr.id;
        if (id.substr(0,2) == 'ft') {
            if (level == 2 || level == 0 ) {
                tr.className = 'hiddenRow';
            }
            else {
                tr.className = 'Hola';
            }
        }
        if (id.substr(0,2) == 'pt') {
            if (level < 2 || level ==4) {
                tr.className = 'hiddenRow';
            }
            else {
                tr.className = '';
            }
        }
    }
    detail_class=document.getElementsByClassName('detail');
    //console.log(detail_class.length)
    if (level == 3) {
        for (var i = 0; i < detail_class.length; i++){
            detail_class[i].innerHTML="Ver"
        }
    }
    else{
            for (var i = 0; i < detail_class.length; i++){
            detail_class[i].innerHTML="Ocultar"
        }
    }
}
function showClassDetail(cid, count) {
    var id_list = Array(count);
    var toHide = 1;
    for (var i = 0; i < count; i++) {

        tid0 = 't' + cid.substr(1) + '_' + (i+1);
        tid = 'f' + tid0;
        tr = document.getElementById(tid);
        if (!tr) {
            tid = 'p' + tid0;
            tr = document.getElementById(tid);
        }
        id_list[i] = tid;
        if (tr.className) {
            toHide = 0;
        }
    }
    for (var i = 0; i < count; i++) {
        tid = id_list[i];

        if (toHide) {
            document.getElementById(tid).className = 'hiddenRow';
            document.getElementById(cid).innerText = "Ver"
        }
        else {
            document.getElementById(tid).className = '';
            document.getElementById(cid).innerText = "Ocultar"
        }
    }
}
function html_escape(s) {
    s = s.replace(/&/g,'&');
    s = s.replace(/</g,'<');
    s = s.replace(/>/g,'>');
    return s;
}
</script>
<div class='heading'>
<h2 style="font-family: Microsoft YaHei">Reporte de pruebas</h4>
<p class='attribute'><strong>Desarrollado por : </strong> Area de Testing PWST</p>
<p class='attribute'><strong>Fecha y hora de inicio : </strong> 2022-09-02 16:12:25</p>
<p class='attribute'><strong>Duracion : </strong> 0:03:47.768761</p>
<p class='attribute'><strong>Resultado : </strong> Total 8，Correctos 3 ，Errores 5 ，Taza de resultado 37.50%</p>

<h3 class='description'>Detalles</h3>
</div>


<p id='show_detail_line'>
<a class="btn btn-primary" href='javascript:showCase(0)'>Resumen 37.50% </a>
<a class="btn btn-warning" href='javascript:showCase(4)'>Errores 5 </a>
<a class="btn btn-danger" href='javascript:showCase(1)'>Fallidos 0 </a>
<a class="btn btn-success" href='javascript:showCase(2)'>Correctos 3 </a>
<a class="btn btn-info" href='javascript:showCase(3)'>Test realizados 8 </a>
</p>
<table id='result_table' class="table table-condensed table-bordered table-hover">
<colgroup>
<col align='left' />
<col align='right' />
<col align='right' />
<col align='right' />
<col align='right' />
<col align='right' />
<col align='right' />
</colgroup>
<tr id='header_row' class="text-center success" style="font-weight: bold;font-size: 14px;">
    <td>Caso de Prueba</td>
    <td>Total</td>
    <td>Correctos</td>
    <td>Fallido</td>
    <td>Error</td>
    <td>Detalles</td>
    <td>Captura del error</td>
</tr>

<tr class='errorClass warning'>
    <td>AutorizacionCredito2.Test: Escenario 1 de Autorizaciones de Credito 2</td>
    <td class="text-center">8</td>
    <td class="text-center">3</td>
    <td class="text-center">0</td>
    <td class="text-center">5</td>
    <td class="text-center"><a href="javascript:showClassDetail('c1',8)" class="detail" id='c1'>Detalles</a></td>
    <td class="text-center"></td>
</tr>

<tr id='pt1_1' class='hiddenRow'>
    <td class='passCase' width='300px'><div class='testcase'>test</div></td>
    <td colspan='5' align='left' width='600px'> <!--print 输出框位置-->
    <!--默认收起错误信息 -Findyou
    <button id='btn_pt1_1' type="button"  class="btn btn-primary btn-xs collapsed" data-toggle="collapse" data-target='#div_pt1_1'>Correcto</button>
    <div id='div_pt1_1' class="collapse">  -->
    <!-- 默认展开错误信息 -Findyou -->
    <button id='btn_pt1_1' type="button"  class="btn btn-primary btn-xs" data-toggle="collapse" data-target='#div_pt1_1'>Correcto</button>
    <div id='div_pt1_1' class="collapse in">
    <pre style="overflow-y:scroll; overflow-x:hidden;height:200px; width:600px; margin:auto; border:1px solid #e1e1e1;">
    
pt1_1: 2022-09-02 16:12:27,378 - root - INFO -  Se abre el chrome
2022-09-02 16:12:28,837 - root - INFO -  Entra a la URL
2022-09-02 16:12:28,972 - root - INFO -  Maximiza la pantalla
2022-09-02 16:12:32,029 - root - INFO -  Cambia al frame


    </pre>
    </div>
    </td>
    <td align="right">
        <a hidden="hidden" href="" target="_blank">
            <img src="" height="200px" width="400px"/>
        </a>
    </td>
</tr>

<tr id='pt1_2' class='hiddenRow'>
    <td class='passCase' width='300px'><div class='testcase'>test_000: Ingresa a la base de datos</div></td>
    <td colspan='5' align='left' width='600px'> <!--print 输出框位置-->
    <!--默认收起错误信息 -Findyou
    <button id='btn_pt1_2' type="button"  class="btn btn-primary btn-xs collapsed" data-toggle="collapse" data-target='#div_pt1_2'>Correcto</button>
    <div id='div_pt1_2' class="collapse">  -->
    <!-- 默认展开错误信息 -Findyou -->
    <button id='btn_pt1_2' type="button"  class="btn btn-primary btn-xs" data-toggle="collapse" data-target='#div_pt1_2'>Correcto</button>
    <div id='div_pt1_2' class="collapse in">
    <pre style="overflow-y:scroll; overflow-x:hidden;height:200px; width:600px; margin:auto; border:1px solid #e1e1e1;">
    
pt1_2: 2022-09-02 16:12:35,115 - root - INFO -  Escribe el usuario
2022-09-02 16:12:35,217 - root - INFO -  Escribe la contraseña
2022-09-02 16:12:35,346 - root - INFO -  Se dio clic en el boton ingresar
2022-09-02 16:12:36,193 - root - INFO -  Ejecutar Enterprise
2022-09-02 16:12:36,195 - root - INFO -  Captura: C:\xampp\htdocs\versiones\automatizaciones\AutoPWST\02AC\report\img  screen：20220902_16_12_36.png
2022-09-02 16:12:40,407 - root - INFO -  Cambia entre pestañas


    </pre>
    </div>
    </td>
    <td align="right">
        <a  href="../../../../img/20220902_16_12_36.png" target="_blank">
            <img src="../../../../img/20220902_16_12_36.png" height="200px" width="400px"/>
        </a>
    </td>
</tr>

<tr id='pt1_3' class='hiddenRow'>
    <td class='passCase' width='300px'><div class='testcase'>test_001: Abre menu y ejecuta pantalla</div></td>
    <td colspan='5' align='left' width='600px'> <!--print 输出框位置-->
    <!--默认收起错误信息 -Findyou
    <button id='btn_pt1_3' type="button"  class="btn btn-primary btn-xs collapsed" data-toggle="collapse" data-target='#div_pt1_3'>Correcto</button>
    <div id='div_pt1_3' class="collapse">  -->
    <!-- 默认展开错误信息 -Findyou -->
    <button id='btn_pt1_3' type="button"  class="btn btn-primary btn-xs" data-toggle="collapse" data-target='#div_pt1_3'>Correcto</button>
    <div id='div_pt1_3' class="collapse in">
    <pre style="overflow-y:scroll; overflow-x:hidden;height:200px; width:600px; margin:auto; border:1px solid #e1e1e1;">
    
pt1_3: 2022-09-02 16:12:51,275 - root - INFO -  Abre el menu completo
2022-09-02 16:12:59,917 - root - INFO -  Abre la pantalla de Autorizaciones de Credito
2022-09-02 16:12:59,987 - root - INFO -  La pantalla ejecutada es Autorizaciones de crédito.
2022-09-02 16:13:02,998 - root - INFO -  Captura: C:\xampp\htdocs\versiones\automatizaciones\AutoPWST\02AC\report\img  screen：20220902_16_13_02.png
2022-09-02 16:13:03,221 - root - INFO -  Se presiona el boton 'Nuevo', para crear un nuevo registro.


    </pre>
    </div>
    </td>
    <td align="right">
        <a  href="../../../../img/20220902_16_13_02.png" target="_blank">
            <img src="../../../../img/20220902_16_13_02.png" height="200px" width="400px"/>
        </a>
    </td>
</tr>

<tr id='ft1_4' class='none'>
    <td class='errorCase' width='300px'><div class='testcase'>test_002: Abre la ventana de nuevo y crear un registro</div></td>
    <td colspan='5' align='left' width='600px'> <!--print 输出框位置-->
    <!--默认收起错误信息 -Findyou
    <button id='btn_ft1_4' type="button"  class="btn btn-primary btn-xs collapsed" data-toggle="collapse" data-target='#div_ft1_4'>Error</button>
    <div id='div_ft1_4' class="collapse">  -->
    <!-- 默认展开错误信息 -Findyou -->
    <button id='btn_ft1_4' type="button"  class="btn btn-primary btn-xs" data-toggle="collapse" data-target='#div_ft1_4'>Error</button>
    <div id='div_ft1_4' class="collapse in">
    <pre style="overflow-y:scroll; overflow-x:hidden;height:200px; width:600px; margin:auto; border:1px solid #e1e1e1;">
    
ft1_4: 2022-09-02 16:13:08,303 - root - INFO -  Se abrio la pantalla para el ingreso de un registro nuevo.
2022-09-02 16:13:08,349 - root - INFO -  El campo 'Empresa' si se encuentra visible.
2022-09-02 16:13:08,389 - root - INFO -  El campo 'Moneda' si se encuentra visible.
2022-09-02 16:13:08,427 - root - INFO -  El campo 'Modo' si se encuentra visible.
2022-09-02 16:13:08,467 - root - INFO -  El campo 'Usuario' si se encuentra visible.
2022-09-02 16:13:08,511 - root - INFO -  El campo 'Cantidad' si se encuentra visible.
2022-09-02 16:13:08,548 - root - INFO -  El campo 'Contraseña' si se encuentra visible.
2022-09-02 16:13:18,009 - root - INFO -  Se dió doble click en el regitro de Empresa.
2022-09-02 16:13:28,466 - root - INFO -  Se dió doble click en el regitro de Moneda.
2022-09-02 16:13:38,886 - root - INFO -  Se dió click en la opción Limite personalizado (evento Documento_OnValidarAutorizacionCreditoGeneral).
2022-09-02 16:13:53,646 - root - INFO -  Se dió doble click en el regitro de Usuario.
2022-09-02 16:13:56,662 - root - INFO -  Captura: C:\xampp\htdocs\versiones\automatizaciones\AutoPWST\02AC\report\img  screen：20220902_16_13_56.png
2022-09-02 16:13:56,871 - root - INFO -  Ingresa de autorización del nuevo registro 
2022-09-02 16:14:00,030 - root - INFO -  Ingresa la contraseña del nuevo registro 
2022-09-02 16:14:04,166 - root - ERROR - No se dió click en el botón Guardar, validar que la acción anterior haya finalizado, que el xpath sea el correcto o que la página no presente lentitud
2022-09-02 16:14:07,175 - root - INFO -  Captura: C:\xampp\htdocs\versiones\automatizaciones\AutoPWST\02AC\report\img  screen：20220902_16_14_07.png
Traceback (most recent call last):
  File "C:\xampp\htdocs\versiones\automatizaciones\AutoPWST\02AC\testCase\AutorizacionCredito2.py", line 46, in test_002
    return nuevoregistro.nuevoregistro(self)
  File "C:\xampp\htdocs\versiones\automatizaciones\AutoPWST\02AC\testCase\nuevoregistro.py", line 298, in nuevoregistro
    Guarda.click()
  File "C:\Users\PWST\Desktop\Automatización\AutoPWST-2.0\AutoPWST-2.0\venv\lib\site-packages\selenium\webdriver\remote\webelement.py", line 88, in click
    self._execute(Command.CLICK_ELEMENT)
  File "C:\Users\PWST\Desktop\Automatización\AutoPWST-2.0\AutoPWST-2.0\venv\lib\site-packages\selenium\webdriver\remote\webelement.py", line 396, in _execute
    return self._parent.execute(command, params)
  File "C:\Users\PWST\Desktop\Automatización\AutoPWST-2.0\AutoPWST-2.0\venv\lib\site-packages\selenium\webdriver\remote\webdriver.py", line 435, in execute
    self.error_handler.check_response(response)
  File "C:\Users\PWST\Desktop\Automatización\AutoPWST-2.0\AutoPWST-2.0\venv\lib\site-packages\selenium\webdriver\remote\errorhandler.py", line 247, in check_response
    raise exception_class(message, screen, stacktrace)
selenium.common.exceptions.ElementClickInterceptedException: Message: element click intercepted: Element &lt;div tabindex="28" id="_7C4CF36D4BF84D13B8EDBA93DFE1F4E4__save_element" name="_7C4CF36D4BF84D13B8EDBA93DFE1F4E4__save_element"&gt;...&lt;/div&gt; is not clickable at point (458, 170). Other element would receive the click: &lt;div class="tabulator-cell" role="gridcell" tabulator-field="field_1" title="" style="width: 100px; text-align: left; height: 30px;"&gt;...&lt;/div&gt;
  (Session info: chrome=105.0.5195.54)
Stacktrace:
Backtrace:
	Ordinal0 [0x00A4DF13+2219795]
	Ordinal0 [0x009E2841+1779777]
	Ordinal0 [0x008F423D+803389]
	Ordinal0 [0x009299D4+1022420]
	Ordinal0 [0x009278C4+1013956]
	Ordinal0 [0x009254AB+1004715]
	Ordinal0 [0x00924117+999703]
	Ordinal0 [0x00919B76+957302]
	Ordinal0 [0x0093E7FC+1107964]
	Ordinal0 [0x009194B4+955572]
	Ordinal0 [0x0093EA14+1108500]
	Ordinal0 [0x0094F192+1175954]
	Ordinal0 [0x0093E616+1107478]
	Ordinal0 [0x00917F89+950153]
	Ordinal0 [0x00918F56+954198]
	GetHandleVerifier [0x00D42CB2+3040210]
	GetHandleVerifier [0x00D32BB4+2974420]
	GetHandleVerifier [0x00AE6A0A+565546]
	GetHandleVerifier [0x00AE5680+560544]
	Ordinal0 [0x009E9A5C+1808988]
	Ordinal0 [0x009EE3A8+1827752]
	Ordinal0 [0x009EE495+1827989]
	Ordinal0 [0x009F80A4+1867940]
	BaseThreadInitThunk [0x756EFA29+25]
	RtlGetAppContainerNamedObjectPath [0x770C7A9E+286]
	RtlGetAppContainerNamedObjectPath [0x770C7A6E+238]



    </pre>
    </div>
    </td>
    <td align="right">
        <a  href="../../../../img/20220902_16_14_07.png" target="_blank">
            <img src="../../../../img/20220902_16_14_07.png" height="200px" width="400px"/>
        </a>
    </td>
</tr>

<tr id='ft1_5' class='none'>
    <td class='errorCase' width='300px'><div class='testcase'>test_003: Repetir el registro creado anteriormente</div></td>
    <td colspan='5' align='left' width='600px'> <!--print 输出框位置-->
    <!--默认收起错误信息 -Findyou
    <button id='btn_ft1_5' type="button"  class="btn btn-primary btn-xs collapsed" data-toggle="collapse" data-target='#div_ft1_5'>Error</button>
    <div id='div_ft1_5' class="collapse">  -->
    <!-- 默认展开错误信息 -Findyou -->
    <button id='btn_ft1_5' type="button"  class="btn btn-primary btn-xs" data-toggle="collapse" data-target='#div_ft1_5'>Error</button>
    <div id='div_ft1_5' class="collapse in">
    <pre style="overflow-y:scroll; overflow-x:hidden;height:200px; width:600px; margin:auto; border:1px solid #e1e1e1;">
    
ft1_5: 2022-09-02 16:14:26,068 - root - ERROR - No se dió click en el botón Refrescar, validar que la acción anterior haya finalizado, que el xpath sea el correcto o que la página no presente lentitud
2022-09-02 16:14:29,085 - root - INFO -  Captura: C:\xampp\htdocs\versiones\automatizaciones\AutoPWST\02AC\report\img  screen：20220902_16_14_29.png
Traceback (most recent call last):
  File "C:\Users\PWST\Desktop\Automatización\AutoPWST-2.0\AutoPWST-2.0\venv\lib\site-packages\urllib3\connection.py", line 174, in _new_conn
    conn = connection.create_connection(
  File "C:\Users\PWST\Desktop\Automatización\AutoPWST-2.0\AutoPWST-2.0\venv\lib\site-packages\urllib3\util\connection.py", line 95, in create_connection
    raise err
  File "C:\Users\PWST\Desktop\Automatización\AutoPWST-2.0\AutoPWST-2.0\venv\lib\site-packages\urllib3\util\connection.py", line 85, in create_connection
    sock.connect(sa)
ConnectionRefusedError: [WinError 10061] No se puede establecer una conexión ya que el equipo de destino denegó expresamente dicha conexión

During handling of the above exception, another exception occurred:

Traceback (most recent call last):
  File "C:\Users\PWST\Desktop\Automatización\AutoPWST-2.0\AutoPWST-2.0\venv\lib\site-packages\urllib3\connectionpool.py", line 703, in urlopen
    httplib_response = self._make_request(
  File "C:\Users\PWST\Desktop\Automatización\AutoPWST-2.0\AutoPWST-2.0\venv\lib\site-packages\urllib3\connectionpool.py", line 398, in _make_request
    conn.request(method, url, **httplib_request_kw)
  File "C:\Users\PWST\Desktop\Automatización\AutoPWST-2.0\AutoPWST-2.0\venv\lib\site-packages\urllib3\connection.py", line 239, in request
    super(HTTPConnection, self).request(method, url, body=body, headers=headers)
  File "C:\Users\PWST\AppData\Local\Programs\Python\Python310\lib\http\client.py", line 1282, in request
    self._send_request(method, url, body, headers, encode_chunked)
  File "C:\Users\PWST\AppData\Local\Programs\Python\Python310\lib\http\client.py", line 1328, in _send_request
    self.endheaders(body, encode_chunked=encode_chunked)
  File "C:\Users\PWST\AppData\Local\Programs\Python\Python310\lib\http\client.py", line 1277, in endheaders
    self._send_output(message_body, encode_chunked=encode_chunked)
  File "C:\Users\PWST\AppData\Local\Programs\Python\Python310\lib\http\client.py", line 1037, in _send_output
    self.send(msg)
  File "C:\Users\PWST\AppData\Local\Programs\Python\Python310\lib\http\client.py", line 975, in send
    self.connect()
  File "C:\Users\PWST\Desktop\Automatización\AutoPWST-2.0\AutoPWST-2.0\venv\lib\site-packages\urllib3\connection.py", line 205, in connect
    conn = self._new_conn()
  File "C:\Users\PWST\Desktop\Automatización\AutoPWST-2.0\AutoPWST-2.0\venv\lib\site-packages\urllib3\connection.py", line 186, in _new_conn
    raise NewConnectionError(
urllib3.exceptions.NewConnectionError: &lt;urllib3.connection.HTTPConnection object at 0x000001B677B3E1D0&gt;: Failed to establish a new connection: [WinError 10061] No se puede establecer una conexión ya que el equipo de destino denegó expresamente dicha conexión

During handling of the above exception, another exception occurred:

Traceback (most recent call last):
  File "C:\xampp\htdocs\versiones\automatizaciones\AutoPWST\02AC\testCase\repetirregistro.py", line 22, in repetirregistro
    Refresca = self.wait.until(conditions.visibility((By.XPATH, Configuracion.btn_Refresca)))
  File "C:\Users\PWST\Desktop\Automatización\AutoPWST-2.0\AutoPWST-2.0\venv\lib\site-packages\selenium\webdriver\support\wait.py", line 81, in until
    value = method(self._driver)
  File "C:\Users\PWST\Desktop\Automatización\AutoPWST-2.0\AutoPWST-2.0\venv\lib\site-packages\selenium\webdriver\support\expected_conditions.py", line 125, in _predicate
    return _element_if_visible(driver.find_element(*locator))
  File "C:\Users\PWST\Desktop\Automatización\AutoPWST-2.0\AutoPWST-2.0\venv\lib\site-packages\selenium\webdriver\remote\webdriver.py", line 857, in find_element
    return self.execute(Command.FIND_ELEMENT, {
  File "C:\Users\PWST\Desktop\Automatización\AutoPWST-2.0\AutoPWST-2.0\venv\lib\site-packages\selenium\webdriver\remote\webdriver.py", line 433, in execute
    response = self.command_executor.execute(driver_command, params)
  File "C:\Users\PWST\Desktop\Automatización\AutoPWST-2.0\AutoPWST-2.0\venv\lib\site-packages\selenium\webdriver\remote\remote_connection.py", line 344, in execute
    return self._request(command_info[0], url, body=data)
  File "C:\Users\PWST\Desktop\Automatización\AutoPWST-2.0\AutoPWST-2.0\venv\lib\site-packages\selenium\webdriver\remote\remote_connection.py", line 366, in _request
    response = self._conn.request(method, url, body=body, headers=headers)
  File "C:\Users\PWST\Desktop\Automatización\AutoPWST-2.0\AutoPWST-2.0\venv\lib\site-packages\urllib3\request.py", line 78, in request
    return self.request_encode_body(
  File "C:\Users\PWST\Desktop\Automatización\AutoPWST-2.0\AutoPWST-2.0\venv\lib\site-packages\urllib3\request.py", line 170, in request_encode_body
    return self.urlopen(method, url, **extra_kw)
  File "C:\Users\PWST\Desktop\Automatización\AutoPWST-2.0\AutoPWST-2.0\venv\lib\site-packages\urllib3\poolmanager.py", line 376, in urlopen
    response = conn.urlopen(method, u.request_uri, **kw)
  File "C:\Users\PWST\Desktop\Automatización\AutoPWST-2.0\AutoPWST-2.0\venv\lib\site-packages\urllib3\connectionpool.py", line 813, in urlopen
    return self.urlopen(
  File "C:\Users\PWST\Desktop\Automatización\AutoPWST-2.0\AutoPWST-2.0\venv\lib\site-packages\urllib3\connectionpool.py", line 813, in urlopen
    return self.urlopen(
  File "C:\Users\PWST\Desktop\Automatización\AutoPWST-2.0\AutoPWST-2.0\venv\lib\site-packages\urllib3\connectionpool.py", line 813, in urlopen
    return self.urlopen(
  File "C:\Users\PWST\Desktop\Automatización\AutoPWST-2.0\AutoPWST-2.0\venv\lib\site-packages\urllib3\connectionpool.py", line 785, in urlopen
    retries = retries.increment(
  File "C:\Users\PWST\Desktop\Automatización\AutoPWST-2.0\AutoPWST-2.0\venv\lib\site-packages\urllib3\util\retry.py", line 592, in increment
    raise MaxRetryError(_pool, url, error or ResponseError(cause))
urllib3.exceptions.MaxRetryError: HTTPConnectionPool(host='localhost', port=60946): Max retries exceeded with url: /session/f095f59d097b585e77ac5de530293375/element (Caused by NewConnectionError('&lt;urllib3.connection.HTTPConnection object at 0x000001B677B3E1D0&gt;: Failed to establish a new connection: [WinError 10061] No se puede establecer una conexión ya que el equipo de destino denegó expresamente dicha conexión'))

During handling of the above exception, another exception occurred:

Traceback (most recent call last):
  File "C:\Users\PWST\Desktop\Automatización\AutoPWST-2.0\AutoPWST-2.0\venv\lib\site-packages\urllib3\connection.py", line 174, in _new_conn
    conn = connection.create_connection(
  File "C:\Users\PWST\Desktop\Automatización\AutoPWST-2.0\AutoPWST-2.0\venv\lib\site-packages\urllib3\util\connection.py", line 95, in create_connection
    raise err
  File "C:\Users\PWST\Desktop\Automatización\AutoPWST-2.0\AutoPWST-2.0\venv\lib\site-packages\urllib3\util\connection.py", line 85, in create_connection
    sock.connect(sa)
ConnectionRefusedError: [WinError 10061] No se puede establecer una conexión ya que el equipo de destino denegó expresamente dicha conexión

During handling of the above exception, another exception occurred:

Traceback (most recent call last):
  File "C:\Users\PWST\Desktop\Automatización\AutoPWST-2.0\AutoPWST-2.0\venv\lib\site-packages\urllib3\connectionpool.py", line 703, in urlopen
    httplib_response = self._make_request(
  File "C:\Users\PWST\Desktop\Automatización\AutoPWST-2.0\AutoPWST-2.0\venv\lib\site-packages\urllib3\connectionpool.py", line 398, in _make_request
    conn.request(method, url, **httplib_request_kw)
  File "C:\Users\PWST\Desktop\Automatización\AutoPWST-2.0\AutoPWST-2.0\venv\lib\site-packages\urllib3\connection.py", line 239, in request
    super(HTTPConnection, self).request(method, url, body=body, headers=headers)
  File "C:\Users\PWST\AppData\Local\Programs\Python\Python310\lib\http\client.py", line 1282, in request
    self._send_request(method, url, body, headers, encode_chunked)
  File "C:\Users\PWST\AppData\Local\Programs\Python\Python310\lib\http\client.py", line 1328, in _send_request
    self.endheaders(body, encode_chunked=encode_chunked)
  File "C:\Users\PWST\AppData\Local\Programs\Python\Python310\lib\http\client.py", line 1277, in endheaders
    self._send_output(message_body, encode_chunked=encode_chunked)
  File "C:\Users\PWST\AppData\Local\Programs\Python\Python310\lib\http\client.py", line 1037, in _send_output
    self.send(msg)
  File "C:\Users\PWST\AppData\Local\Programs\Python\Python310\lib\http\client.py", line 975, in send
    self.connect()
  File "C:\Users\PWST\Desktop\Automatización\AutoPWST-2.0\AutoPWST-2.0\venv\lib\site-packages\urllib3\connection.py", line 205, in connect
    conn = self._new_conn()
  File "C:\Users\PWST\Desktop\Automatización\AutoPWST-2.0\AutoPWST-2.0\venv\lib\site-packages\urllib3\connection.py", line 186, in _new_conn
    raise NewConnectionError(
urllib3.exceptions.NewConnectionError: &lt;urllib3.connection.HTTPConnection object at 0x000001B677B3F9A0&gt;: Failed to establish a new connection: [WinError 10061] No se puede establecer una conexión ya que el equipo de destino denegó expresamente dicha conexión

During handling of the above exception, another exception occurred:

Traceback (most recent call last):
  File "C:\xampp\htdocs\versiones\automatizaciones\AutoPWST\02AC\testCase\AutorizacionCredito2.py", line 50, in test_003
    return repetirregistro.repetirregistro(self)
  File "C:\xampp\htdocs\versiones\automatizaciones\AutoPWST\02AC\testCase\repetirregistro.py", line 33, in repetirregistro
    self.driver.get_screenshot_as_file(img_name)
  File "C:\Users\PWST\Desktop\Automatización\AutoPWST-2.0\AutoPWST-2.0\venv\lib\site-packages\selenium\webdriver\remote\webdriver.py", line 928, in get_screenshot_as_file
    png = self.get_screenshot_as_png()
  File "C:\Users\PWST\Desktop\Automatización\AutoPWST-2.0\AutoPWST-2.0\venv\lib\site-packages\selenium\webdriver\remote\webdriver.py", line 964, in get_screenshot_as_png
    return b64decode(self.get_screenshot_as_base64().encode('ascii'))
  File "C:\Users\PWST\Desktop\Automatización\AutoPWST-2.0\AutoPWST-2.0\venv\lib\site-packages\selenium\webdriver\remote\webdriver.py", line 976, in get_screenshot_as_base64
    return self.execute(Command.SCREENSHOT)['value']
  File "C:\Users\PWST\Desktop\Automatización\AutoPWST-2.0\AutoPWST-2.0\venv\lib\site-packages\selenium\webdriver\remote\webdriver.py", line 433, in execute
    response = self.command_executor.execute(driver_command, params)
  File "C:\Users\PWST\Desktop\Automatización\AutoPWST-2.0\AutoPWST-2.0\venv\lib\site-packages\selenium\webdriver\remote\remote_connection.py", line 344, in execute
    return self._request(command_info[0], url, body=data)
  File "C:\Users\PWST\Desktop\Automatización\AutoPWST-2.0\AutoPWST-2.0\venv\lib\site-packages\selenium\webdriver\remote\remote_connection.py", line 366, in _request
    response = self._conn.request(method, url, body=body, headers=headers)
  File "C:\Users\PWST\Desktop\Automatización\AutoPWST-2.0\AutoPWST-2.0\venv\lib\site-packages\urllib3\request.py", line 74, in request
    return self.request_encode_url(
  File "C:\Users\PWST\Desktop\Automatización\AutoPWST-2.0\AutoPWST-2.0\venv\lib\site-packages\urllib3\request.py", line 96, in request_encode_url
    return self.urlopen(method, url, **extra_kw)
  File "C:\Users\PWST\Desktop\Automatización\AutoPWST-2.0\AutoPWST-2.0\venv\lib\site-packages\urllib3\poolmanager.py", line 376, in urlopen
    response = conn.urlopen(method, u.request_uri, **kw)
  File "C:\Users\PWST\Desktop\Automatización\AutoPWST-2.0\AutoPWST-2.0\venv\lib\site-packages\urllib3\connectionpool.py", line 813, in urlopen
    return self.urlopen(
  File "C:\Users\PWST\Desktop\Automatización\AutoPWST-2.0\AutoPWST-2.0\venv\lib\site-packages\urllib3\connectionpool.py", line 813, in urlopen
    return self.urlopen(
  File "C:\Users\PWST\Desktop\Automatización\AutoPWST-2.0\AutoPWST-2.0\venv\lib\site-packages\urllib3\connectionpool.py", line 813, in urlopen
    return self.urlopen(
  File "C:\Users\PWST\Desktop\Automatización\AutoPWST-2.0\AutoPWST-2.0\venv\lib\site-packages\urllib3\connectionpool.py", line 785, in urlopen
    retries = retries.increment(
  File "C:\Users\PWST\Desktop\Automatización\AutoPWST-2.0\AutoPWST-2.0\venv\lib\site-packages\urllib3\util\retry.py", line 592, in increment
    raise MaxRetryError(_pool, url, error or ResponseError(cause))
urllib3.exceptions.MaxRetryError: HTTPConnectionPool(host='localhost', port=60946): Max retries exceeded with url: /session/f095f59d097b585e77ac5de530293375/screenshot (Caused by NewConnectionError('&lt;urllib3.connection.HTTPConnection object at 0x000001B677B3F9A0&gt;: Failed to establish a new connection: [WinError 10061] No se puede establecer una conexión ya que el equipo de destino denegó expresamente dicha conexión'))


    </pre>
    </div>
    </td>
    <td align="right">
        <a  href="../../../../img/20220902_16_14_29.png" target="_blank">
            <img src="../../../../img/20220902_16_14_29.png" height="200px" width="400px"/>
        </a>
    </td>
</tr>

<tr id='ft1_6' class='none'>
    <td class='errorCase' width='300px'><div class='testcase'>test_004: Modificar el registro</div></td>
    <td colspan='5' align='left' width='600px'> <!--print 输出框位置-->
    <!--默认收起错误信息 -Findyou
    <button id='btn_ft1_6' type="button"  class="btn btn-primary btn-xs collapsed" data-toggle="collapse" data-target='#div_ft1_6'>Error</button>
    <div id='div_ft1_6' class="collapse">  -->
    <!-- 默认展开错误信息 -Findyou -->
    <button id='btn_ft1_6' type="button"  class="btn btn-primary btn-xs" data-toggle="collapse" data-target='#div_ft1_6'>Error</button>
    <div id='div_ft1_6' class="collapse in">
    <pre style="overflow-y:scroll; overflow-x:hidden;height:200px; width:600px; margin:auto; border:1px solid #e1e1e1;">
    
ft1_6: 2022-09-02 16:15:01,915 - root - ERROR - No se dió click en el botón Refrescar, validar que la acción anterior haya finalizado, que el xpath sea el correcto o que la página no presente lentitud
2022-09-02 16:15:04,921 - root - INFO -  Captura: C:\xampp\htdocs\versiones\automatizaciones\AutoPWST\02AC\report\img  screen：20220902_16_15_04.png
Traceback (most recent call last):
  File "C:\Users\PWST\Desktop\Automatización\AutoPWST-2.0\AutoPWST-2.0\venv\lib\site-packages\urllib3\connection.py", line 174, in _new_conn
    conn = connection.create_connection(
  File "C:\Users\PWST\Desktop\Automatización\AutoPWST-2.0\AutoPWST-2.0\venv\lib\site-packages\urllib3\util\connection.py", line 95, in create_connection
    raise err
  File "C:\Users\PWST\Desktop\Automatización\AutoPWST-2.0\AutoPWST-2.0\venv\lib\site-packages\urllib3\util\connection.py", line 85, in create_connection
    sock.connect(sa)
ConnectionRefusedError: [WinError 10061] No se puede establecer una conexión ya que el equipo de destino denegó expresamente dicha conexión

During handling of the above exception, another exception occurred:

Traceback (most recent call last):
  File "C:\Users\PWST\Desktop\Automatización\AutoPWST-2.0\AutoPWST-2.0\venv\lib\site-packages\urllib3\connectionpool.py", line 703, in urlopen
    httplib_response = self._make_request(
  File "C:\Users\PWST\Desktop\Automatización\AutoPWST-2.0\AutoPWST-2.0\venv\lib\site-packages\urllib3\connectionpool.py", line 398, in _make_request
    conn.request(method, url, **httplib_request_kw)
  File "C:\Users\PWST\Desktop\Automatización\AutoPWST-2.0\AutoPWST-2.0\venv\lib\site-packages\urllib3\connection.py", line 239, in request
    super(HTTPConnection, self).request(method, url, body=body, headers=headers)
  File "C:\Users\PWST\AppData\Local\Programs\Python\Python310\lib\http\client.py", line 1282, in request
    self._send_request(method, url, body, headers, encode_chunked)
  File "C:\Users\PWST\AppData\Local\Programs\Python\Python310\lib\http\client.py", line 1328, in _send_request
    self.endheaders(body, encode_chunked=encode_chunked)
  File "C:\Users\PWST\AppData\Local\Programs\Python\Python310\lib\http\client.py", line 1277, in endheaders
    self._send_output(message_body, encode_chunked=encode_chunked)
  File "C:\Users\PWST\AppData\Local\Programs\Python\Python310\lib\http\client.py", line 1037, in _send_output
    self.send(msg)
  File "C:\Users\PWST\AppData\Local\Programs\Python\Python310\lib\http\client.py", line 975, in send
    self.connect()
  File "C:\Users\PWST\Desktop\Automatización\AutoPWST-2.0\AutoPWST-2.0\venv\lib\site-packages\urllib3\connection.py", line 205, in connect
    conn = self._new_conn()
  File "C:\Users\PWST\Desktop\Automatización\AutoPWST-2.0\AutoPWST-2.0\venv\lib\site-packages\urllib3\connection.py", line 186, in _new_conn
    raise NewConnectionError(
urllib3.exceptions.NewConnectionError: &lt;urllib3.connection.HTTPConnection object at 0x000001B677B3F130&gt;: Failed to establish a new connection: [WinError 10061] No se puede establecer una conexión ya que el equipo de destino denegó expresamente dicha conexión

During handling of the above exception, another exception occurred:

Traceback (most recent call last):
  File "C:\xampp\htdocs\versiones\automatizaciones\AutoPWST\02AC\testCase\modificarregistro.py", line 22, in modificarregistro
    Refresca2 = self.wait.until(conditions.visibility((By.XPATH, Configuracion.btn_Refresca)))
  File "C:\Users\PWST\Desktop\Automatización\AutoPWST-2.0\AutoPWST-2.0\venv\lib\site-packages\selenium\webdriver\support\wait.py", line 81, in until
    value = method(self._driver)
  File "C:\Users\PWST\Desktop\Automatización\AutoPWST-2.0\AutoPWST-2.0\venv\lib\site-packages\selenium\webdriver\support\expected_conditions.py", line 125, in _predicate
    return _element_if_visible(driver.find_element(*locator))
  File "C:\Users\PWST\Desktop\Automatización\AutoPWST-2.0\AutoPWST-2.0\venv\lib\site-packages\selenium\webdriver\remote\webdriver.py", line 857, in find_element
    return self.execute(Command.FIND_ELEMENT, {
  File "C:\Users\PWST\Desktop\Automatización\AutoPWST-2.0\AutoPWST-2.0\venv\lib\site-packages\selenium\webdriver\remote\webdriver.py", line 433, in execute
    response = self.command_executor.execute(driver_command, params)
  File "C:\Users\PWST\Desktop\Automatización\AutoPWST-2.0\AutoPWST-2.0\venv\lib\site-packages\selenium\webdriver\remote\remote_connection.py", line 344, in execute
    return self._request(command_info[0], url, body=data)
  File "C:\Users\PWST\Desktop\Automatización\AutoPWST-2.0\AutoPWST-2.0\venv\lib\site-packages\selenium\webdriver\remote\remote_connection.py", line 366, in _request
    response = self._conn.request(method, url, body=body, headers=headers)
  File "C:\Users\PWST\Desktop\Automatización\AutoPWST-2.0\AutoPWST-2.0\venv\lib\site-packages\urllib3\request.py", line 78, in request
    return self.request_encode_body(
  File "C:\Users\PWST\Desktop\Automatización\AutoPWST-2.0\AutoPWST-2.0\venv\lib\site-packages\urllib3\request.py", line 170, in request_encode_body
    return self.urlopen(method, url, **extra_kw)
  File "C:\Users\PWST\Desktop\Automatización\AutoPWST-2.0\AutoPWST-2.0\venv\lib\site-packages\urllib3\poolmanager.py", line 376, in urlopen
    response = conn.urlopen(method, u.request_uri, **kw)
  File "C:\Users\PWST\Desktop\Automatización\AutoPWST-2.0\AutoPWST-2.0\venv\lib\site-packages\urllib3\connectionpool.py", line 813, in urlopen
    return self.urlopen(
  File "C:\Users\PWST\Desktop\Automatización\AutoPWST-2.0\AutoPWST-2.0\venv\lib\site-packages\urllib3\connectionpool.py", line 813, in urlopen
    return self.urlopen(
  File "C:\Users\PWST\Desktop\Automatización\AutoPWST-2.0\AutoPWST-2.0\venv\lib\site-packages\urllib3\connectionpool.py", line 813, in urlopen
    return self.urlopen(
  File "C:\Users\PWST\Desktop\Automatización\AutoPWST-2.0\AutoPWST-2.0\venv\lib\site-packages\urllib3\connectionpool.py", line 785, in urlopen
    retries = retries.increment(
  File "C:\Users\PWST\Desktop\Automatización\AutoPWST-2.0\AutoPWST-2.0\venv\lib\site-packages\urllib3\util\retry.py", line 592, in increment
    raise MaxRetryError(_pool, url, error or ResponseError(cause))
urllib3.exceptions.MaxRetryError: HTTPConnectionPool(host='localhost', port=60946): Max retries exceeded with url: /session/f095f59d097b585e77ac5de530293375/element (Caused by NewConnectionError('&lt;urllib3.connection.HTTPConnection object at 0x000001B677B3F130&gt;: Failed to establish a new connection: [WinError 10061] No se puede establecer una conexión ya que el equipo de destino denegó expresamente dicha conexión'))

During handling of the above exception, another exception occurred:

Traceback (most recent call last):
  File "C:\Users\PWST\Desktop\Automatización\AutoPWST-2.0\AutoPWST-2.0\venv\lib\site-packages\urllib3\connection.py", line 174, in _new_conn
    conn = connection.create_connection(
  File "C:\Users\PWST\Desktop\Automatización\AutoPWST-2.0\AutoPWST-2.0\venv\lib\site-packages\urllib3\util\connection.py", line 95, in create_connection
    raise err
  File "C:\Users\PWST\Desktop\Automatización\AutoPWST-2.0\AutoPWST-2.0\venv\lib\site-packages\urllib3\util\connection.py", line 85, in create_connection
    sock.connect(sa)
ConnectionRefusedError: [WinError 10061] No se puede establecer una conexión ya que el equipo de destino denegó expresamente dicha conexión

During handling of the above exception, another exception occurred:

Traceback (most recent call last):
  File "C:\Users\PWST\Desktop\Automatización\AutoPWST-2.0\AutoPWST-2.0\venv\lib\site-packages\urllib3\connectionpool.py", line 703, in urlopen
    httplib_response = self._make_request(
  File "C:\Users\PWST\Desktop\Automatización\AutoPWST-2.0\AutoPWST-2.0\venv\lib\site-packages\urllib3\connectionpool.py", line 398, in _make_request
    conn.request(method, url, **httplib_request_kw)
  File "C:\Users\PWST\Desktop\Automatización\AutoPWST-2.0\AutoPWST-2.0\venv\lib\site-packages\urllib3\connection.py", line 239, in request
    super(HTTPConnection, self).request(method, url, body=body, headers=headers)
  File "C:\Users\PWST\AppData\Local\Programs\Python\Python310\lib\http\client.py", line 1282, in request
    self._send_request(method, url, body, headers, encode_chunked)
  File "C:\Users\PWST\AppData\Local\Programs\Python\Python310\lib\http\client.py", line 1328, in _send_request
    self.endheaders(body, encode_chunked=encode_chunked)
  File "C:\Users\PWST\AppData\Local\Programs\Python\Python310\lib\http\client.py", line 1277, in endheaders
    self._send_output(message_body, encode_chunked=encode_chunked)
  File "C:\Users\PWST\AppData\Local\Programs\Python\Python310\lib\http\client.py", line 1037, in _send_output
    self.send(msg)
  File "C:\Users\PWST\AppData\Local\Programs\Python\Python310\lib\http\client.py", line 975, in send
    self.connect()
  File "C:\Users\PWST\Desktop\Automatización\AutoPWST-2.0\AutoPWST-2.0\venv\lib\site-packages\urllib3\connection.py", line 205, in connect
    conn = self._new_conn()
  File "C:\Users\PWST\Desktop\Automatización\AutoPWST-2.0\AutoPWST-2.0\venv\lib\site-packages\urllib3\connection.py", line 186, in _new_conn
    raise NewConnectionError(
urllib3.exceptions.NewConnectionError: &lt;urllib3.connection.HTTPConnection object at 0x000001B677B3EB60&gt;: Failed to establish a new connection: [WinError 10061] No se puede establecer una conexión ya que el equipo de destino denegó expresamente dicha conexión

During handling of the above exception, another exception occurred:

Traceback (most recent call last):
  File "C:\xampp\htdocs\versiones\automatizaciones\AutoPWST\02AC\testCase\AutorizacionCredito2.py", line 54, in test_004
    return modificarregistro.modificarregistro(self)
  File "C:\xampp\htdocs\versiones\automatizaciones\AutoPWST\02AC\testCase\modificarregistro.py", line 33, in modificarregistro
    self.driver.get_screenshot_as_file(img_name)
  File "C:\Users\PWST\Desktop\Automatización\AutoPWST-2.0\AutoPWST-2.0\venv\lib\site-packages\selenium\webdriver\remote\webdriver.py", line 928, in get_screenshot_as_file
    png = self.get_screenshot_as_png()
  File "C:\Users\PWST\Desktop\Automatización\AutoPWST-2.0\AutoPWST-2.0\venv\lib\site-packages\selenium\webdriver\remote\webdriver.py", line 964, in get_screenshot_as_png
    return b64decode(self.get_screenshot_as_base64().encode('ascii'))
  File "C:\Users\PWST\Desktop\Automatización\AutoPWST-2.0\AutoPWST-2.0\venv\lib\site-packages\selenium\webdriver\remote\webdriver.py", line 976, in get_screenshot_as_base64
    return self.execute(Command.SCREENSHOT)['value']
  File "C:\Users\PWST\Desktop\Automatización\AutoPWST-2.0\AutoPWST-2.0\venv\lib\site-packages\selenium\webdriver\remote\webdriver.py", line 433, in execute
    response = self.command_executor.execute(driver_command, params)
  File "C:\Users\PWST\Desktop\Automatización\AutoPWST-2.0\AutoPWST-2.0\venv\lib\site-packages\selenium\webdriver\remote\remote_connection.py", line 344, in execute
    return self._request(command_info[0], url, body=data)
  File "C:\Users\PWST\Desktop\Automatización\AutoPWST-2.0\AutoPWST-2.0\venv\lib\site-packages\selenium\webdriver\remote\remote_connection.py", line 366, in _request
    response = self._conn.request(method, url, body=body, headers=headers)
  File "C:\Users\PWST\Desktop\Automatización\AutoPWST-2.0\AutoPWST-2.0\venv\lib\site-packages\urllib3\request.py", line 74, in request
    return self.request_encode_url(
  File "C:\Users\PWST\Desktop\Automatización\AutoPWST-2.0\AutoPWST-2.0\venv\lib\site-packages\urllib3\request.py", line 96, in request_encode_url
    return self.urlopen(method, url, **extra_kw)
  File "C:\Users\PWST\Desktop\Automatización\AutoPWST-2.0\AutoPWST-2.0\venv\lib\site-packages\urllib3\poolmanager.py", line 376, in urlopen
    response = conn.urlopen(method, u.request_uri, **kw)
  File "C:\Users\PWST\Desktop\Automatización\AutoPWST-2.0\AutoPWST-2.0\venv\lib\site-packages\urllib3\connectionpool.py", line 813, in urlopen
    return self.urlopen(
  File "C:\Users\PWST\Desktop\Automatización\AutoPWST-2.0\AutoPWST-2.0\venv\lib\site-packages\urllib3\connectionpool.py", line 813, in urlopen
    return self.urlopen(
  File "C:\Users\PWST\Desktop\Automatización\AutoPWST-2.0\AutoPWST-2.0\venv\lib\site-packages\urllib3\connectionpool.py", line 813, in urlopen
    return self.urlopen(
  File "C:\Users\PWST\Desktop\Automatización\AutoPWST-2.0\AutoPWST-2.0\venv\lib\site-packages\urllib3\connectionpool.py", line 785, in urlopen
    retries = retries.increment(
  File "C:\Users\PWST\Desktop\Automatización\AutoPWST-2.0\AutoPWST-2.0\venv\lib\site-packages\urllib3\util\retry.py", line 592, in increment
    raise MaxRetryError(_pool, url, error or ResponseError(cause))
urllib3.exceptions.MaxRetryError: HTTPConnectionPool(host='localhost', port=60946): Max retries exceeded with url: /session/f095f59d097b585e77ac5de530293375/screenshot (Caused by NewConnectionError('&lt;urllib3.connection.HTTPConnection object at 0x000001B677B3EB60&gt;: Failed to establish a new connection: [WinError 10061] No se puede establecer una conexión ya que el equipo de destino denegó expresamente dicha conexión'))


    </pre>
    </div>
    </td>
    <td align="right">
        <a  href="../../../../img/20220902_16_15_04.png" target="_blank">
            <img src="../../../../img/20220902_16_15_04.png" height="200px" width="400px"/>
        </a>
    </td>
</tr>

<tr id='ft1_7' class='none'>
    <td class='errorCase' width='300px'><div class='testcase'>test_005: Eliminar el registro creado</div></td>
    <td colspan='5' align='left' width='600px'> <!--print 输出框位置-->
    <!--默认收起错误信息 -Findyou
    <button id='btn_ft1_7' type="button"  class="btn btn-primary btn-xs collapsed" data-toggle="collapse" data-target='#div_ft1_7'>Error</button>
    <div id='div_ft1_7' class="collapse">  -->
    <!-- 默认展开错误信息 -Findyou -->
    <button id='btn_ft1_7' type="button"  class="btn btn-primary btn-xs" data-toggle="collapse" data-target='#div_ft1_7'>Error</button>
    <div id='div_ft1_7' class="collapse in">
    <pre style="overflow-y:scroll; overflow-x:hidden;height:200px; width:600px; margin:auto; border:1px solid #e1e1e1;">
    
ft1_7: 2022-09-02 16:15:37,739 - root - ERROR - No se dió click en el botón Refrescar, validar que la acción anterior haya finalizado, que el xpath sea el correcto o que la página no presente lentitud
2022-09-02 16:15:40,744 - root - INFO -  Captura: C:\xampp\htdocs\versiones\automatizaciones\AutoPWST\02AC\report\img  screen：20220902_16_15_40.png
Traceback (most recent call last):
  File "C:\Users\PWST\Desktop\Automatización\AutoPWST-2.0\AutoPWST-2.0\venv\lib\site-packages\urllib3\connection.py", line 174, in _new_conn
    conn = connection.create_connection(
  File "C:\Users\PWST\Desktop\Automatización\AutoPWST-2.0\AutoPWST-2.0\venv\lib\site-packages\urllib3\util\connection.py", line 95, in create_connection
    raise err
  File "C:\Users\PWST\Desktop\Automatización\AutoPWST-2.0\AutoPWST-2.0\venv\lib\site-packages\urllib3\util\connection.py", line 85, in create_connection
    sock.connect(sa)
ConnectionRefusedError: [WinError 10061] No se puede establecer una conexión ya que el equipo de destino denegó expresamente dicha conexión

During handling of the above exception, another exception occurred:

Traceback (most recent call last):
  File "C:\Users\PWST\Desktop\Automatización\AutoPWST-2.0\AutoPWST-2.0\venv\lib\site-packages\urllib3\connectionpool.py", line 703, in urlopen
    httplib_response = self._make_request(
  File "C:\Users\PWST\Desktop\Automatización\AutoPWST-2.0\AutoPWST-2.0\venv\lib\site-packages\urllib3\connectionpool.py", line 398, in _make_request
    conn.request(method, url, **httplib_request_kw)
  File "C:\Users\PWST\Desktop\Automatización\AutoPWST-2.0\AutoPWST-2.0\venv\lib\site-packages\urllib3\connection.py", line 239, in request
    super(HTTPConnection, self).request(method, url, body=body, headers=headers)
  File "C:\Users\PWST\AppData\Local\Programs\Python\Python310\lib\http\client.py", line 1282, in request
    self._send_request(method, url, body, headers, encode_chunked)
  File "C:\Users\PWST\AppData\Local\Programs\Python\Python310\lib\http\client.py", line 1328, in _send_request
    self.endheaders(body, encode_chunked=encode_chunked)
  File "C:\Users\PWST\AppData\Local\Programs\Python\Python310\lib\http\client.py", line 1277, in endheaders
    self._send_output(message_body, encode_chunked=encode_chunked)
  File "C:\Users\PWST\AppData\Local\Programs\Python\Python310\lib\http\client.py", line 1037, in _send_output
    self.send(msg)
  File "C:\Users\PWST\AppData\Local\Programs\Python\Python310\lib\http\client.py", line 975, in send
    self.connect()
  File "C:\Users\PWST\Desktop\Automatización\AutoPWST-2.0\AutoPWST-2.0\venv\lib\site-packages\urllib3\connection.py", line 205, in connect
    conn = self._new_conn()
  File "C:\Users\PWST\Desktop\Automatización\AutoPWST-2.0\AutoPWST-2.0\venv\lib\site-packages\urllib3\connection.py", line 186, in _new_conn
    raise NewConnectionError(
urllib3.exceptions.NewConnectionError: &lt;urllib3.connection.HTTPConnection object at 0x000001B677B3F850&gt;: Failed to establish a new connection: [WinError 10061] No se puede establecer una conexión ya que el equipo de destino denegó expresamente dicha conexión

During handling of the above exception, another exception occurred:

Traceback (most recent call last):
  File "C:\xampp\htdocs\versiones\automatizaciones\AutoPWST\02AC\testCase\eliminarregistro.py", line 21, in eliminarregistro
    Refresca3 = self.wait.until(conditions.visibility((By.XPATH, Configuracion.btn_Refresca)))
  File "C:\Users\PWST\Desktop\Automatización\AutoPWST-2.0\AutoPWST-2.0\venv\lib\site-packages\selenium\webdriver\support\wait.py", line 81, in until
    value = method(self._driver)
  File "C:\Users\PWST\Desktop\Automatización\AutoPWST-2.0\AutoPWST-2.0\venv\lib\site-packages\selenium\webdriver\support\expected_conditions.py", line 125, in _predicate
    return _element_if_visible(driver.find_element(*locator))
  File "C:\Users\PWST\Desktop\Automatización\AutoPWST-2.0\AutoPWST-2.0\venv\lib\site-packages\selenium\webdriver\remote\webdriver.py", line 857, in find_element
    return self.execute(Command.FIND_ELEMENT, {
  File "C:\Users\PWST\Desktop\Automatización\AutoPWST-2.0\AutoPWST-2.0\venv\lib\site-packages\selenium\webdriver\remote\webdriver.py", line 433, in execute
    response = self.command_executor.execute(driver_command, params)
  File "C:\Users\PWST\Desktop\Automatización\AutoPWST-2.0\AutoPWST-2.0\venv\lib\site-packages\selenium\webdriver\remote\remote_connection.py", line 344, in execute
    return self._request(command_info[0], url, body=data)
  File "C:\Users\PWST\Desktop\Automatización\AutoPWST-2.0\AutoPWST-2.0\venv\lib\site-packages\selenium\webdriver\remote\remote_connection.py", line 366, in _request
    response = self._conn.request(method, url, body=body, headers=headers)
  File "C:\Users\PWST\Desktop\Automatización\AutoPWST-2.0\AutoPWST-2.0\venv\lib\site-packages\urllib3\request.py", line 78, in request
    return self.request_encode_body(
  File "C:\Users\PWST\Desktop\Automatización\AutoPWST-2.0\AutoPWST-2.0\venv\lib\site-packages\urllib3\request.py", line 170, in request_encode_body
    return self.urlopen(method, url, **extra_kw)
  File "C:\Users\PWST\Desktop\Automatización\AutoPWST-2.0\AutoPWST-2.0\venv\lib\site-packages\urllib3\poolmanager.py", line 376, in urlopen
    response = conn.urlopen(method, u.request_uri, **kw)
  File "C:\Users\PWST\Desktop\Automatización\AutoPWST-2.0\AutoPWST-2.0\venv\lib\site-packages\urllib3\connectionpool.py", line 813, in urlopen
    return self.urlopen(
  File "C:\Users\PWST\Desktop\Automatización\AutoPWST-2.0\AutoPWST-2.0\venv\lib\site-packages\urllib3\connectionpool.py", line 813, in urlopen
    return self.urlopen(
  File "C:\Users\PWST\Desktop\Automatización\AutoPWST-2.0\AutoPWST-2.0\venv\lib\site-packages\urllib3\connectionpool.py", line 813, in urlopen
    return self.urlopen(
  File "C:\Users\PWST\Desktop\Automatización\AutoPWST-2.0\AutoPWST-2.0\venv\lib\site-packages\urllib3\connectionpool.py", line 785, in urlopen
    retries = retries.increment(
  File "C:\Users\PWST\Desktop\Automatización\AutoPWST-2.0\AutoPWST-2.0\venv\lib\site-packages\urllib3\util\retry.py", line 592, in increment
    raise MaxRetryError(_pool, url, error or ResponseError(cause))
urllib3.exceptions.MaxRetryError: HTTPConnectionPool(host='localhost', port=60946): Max retries exceeded with url: /session/f095f59d097b585e77ac5de530293375/element (Caused by NewConnectionError('&lt;urllib3.connection.HTTPConnection object at 0x000001B677B3F850&gt;: Failed to establish a new connection: [WinError 10061] No se puede establecer una conexión ya que el equipo de destino denegó expresamente dicha conexión'))

During handling of the above exception, another exception occurred:

Traceback (most recent call last):
  File "C:\Users\PWST\Desktop\Automatización\AutoPWST-2.0\AutoPWST-2.0\venv\lib\site-packages\urllib3\connection.py", line 174, in _new_conn
    conn = connection.create_connection(
  File "C:\Users\PWST\Desktop\Automatización\AutoPWST-2.0\AutoPWST-2.0\venv\lib\site-packages\urllib3\util\connection.py", line 95, in create_connection
    raise err
  File "C:\Users\PWST\Desktop\Automatización\AutoPWST-2.0\AutoPWST-2.0\venv\lib\site-packages\urllib3\util\connection.py", line 85, in create_connection
    sock.connect(sa)
ConnectionRefusedError: [WinError 10061] No se puede establecer una conexión ya que el equipo de destino denegó expresamente dicha conexión

During handling of the above exception, another exception occurred:

Traceback (most recent call last):
  File "C:\Users\PWST\Desktop\Automatización\AutoPWST-2.0\AutoPWST-2.0\venv\lib\site-packages\urllib3\connectionpool.py", line 703, in urlopen
    httplib_response = self._make_request(
  File "C:\Users\PWST\Desktop\Automatización\AutoPWST-2.0\AutoPWST-2.0\venv\lib\site-packages\urllib3\connectionpool.py", line 398, in _make_request
    conn.request(method, url, **httplib_request_kw)
  File "C:\Users\PWST\Desktop\Automatización\AutoPWST-2.0\AutoPWST-2.0\venv\lib\site-packages\urllib3\connection.py", line 239, in request
    super(HTTPConnection, self).request(method, url, body=body, headers=headers)
  File "C:\Users\PWST\AppData\Local\Programs\Python\Python310\lib\http\client.py", line 1282, in request
    self._send_request(method, url, body, headers, encode_chunked)
  File "C:\Users\PWST\AppData\Local\Programs\Python\Python310\lib\http\client.py", line 1328, in _send_request
    self.endheaders(body, encode_chunked=encode_chunked)
  File "C:\Users\PWST\AppData\Local\Programs\Python\Python310\lib\http\client.py", line 1277, in endheaders
    self._send_output(message_body, encode_chunked=encode_chunked)
  File "C:\Users\PWST\AppData\Local\Programs\Python\Python310\lib\http\client.py", line 1037, in _send_output
    self.send(msg)
  File "C:\Users\PWST\AppData\Local\Programs\Python\Python310\lib\http\client.py", line 975, in send
    self.connect()
  File "C:\Users\PWST\Desktop\Automatización\AutoPWST-2.0\AutoPWST-2.0\venv\lib\site-packages\urllib3\connection.py", line 205, in connect
    conn = self._new_conn()
  File "C:\Users\PWST\Desktop\Automatización\AutoPWST-2.0\AutoPWST-2.0\venv\lib\site-packages\urllib3\connection.py", line 186, in _new_conn
    raise NewConnectionError(
urllib3.exceptions.NewConnectionError: &lt;urllib3.connection.HTTPConnection object at 0x000001B677B3F520&gt;: Failed to establish a new connection: [WinError 10061] No se puede establecer una conexión ya que el equipo de destino denegó expresamente dicha conexión

During handling of the above exception, another exception occurred:

Traceback (most recent call last):
  File "C:\xampp\htdocs\versiones\automatizaciones\AutoPWST\02AC\testCase\AutorizacionCredito2.py", line 58, in test_005
    return eliminarregistro.eliminarregistro(self)
  File "C:\xampp\htdocs\versiones\automatizaciones\AutoPWST\02AC\testCase\eliminarregistro.py", line 32, in eliminarregistro
    self.driver.get_screenshot_as_file(img_name)
  File "C:\Users\PWST\Desktop\Automatización\AutoPWST-2.0\AutoPWST-2.0\venv\lib\site-packages\selenium\webdriver\remote\webdriver.py", line 928, in get_screenshot_as_file
    png = self.get_screenshot_as_png()
  File "C:\Users\PWST\Desktop\Automatización\AutoPWST-2.0\AutoPWST-2.0\venv\lib\site-packages\selenium\webdriver\remote\webdriver.py", line 964, in get_screenshot_as_png
    return b64decode(self.get_screenshot_as_base64().encode('ascii'))
  File "C:\Users\PWST\Desktop\Automatización\AutoPWST-2.0\AutoPWST-2.0\venv\lib\site-packages\selenium\webdriver\remote\webdriver.py", line 976, in get_screenshot_as_base64
    return self.execute(Command.SCREENSHOT)['value']
  File "C:\Users\PWST\Desktop\Automatización\AutoPWST-2.0\AutoPWST-2.0\venv\lib\site-packages\selenium\webdriver\remote\webdriver.py", line 433, in execute
    response = self.command_executor.execute(driver_command, params)
  File "C:\Users\PWST\Desktop\Automatización\AutoPWST-2.0\AutoPWST-2.0\venv\lib\site-packages\selenium\webdriver\remote\remote_connection.py", line 344, in execute
    return self._request(command_info[0], url, body=data)
  File "C:\Users\PWST\Desktop\Automatización\AutoPWST-2.0\AutoPWST-2.0\venv\lib\site-packages\selenium\webdriver\remote\remote_connection.py", line 366, in _request
    response = self._conn.request(method, url, body=body, headers=headers)
  File "C:\Users\PWST\Desktop\Automatización\AutoPWST-2.0\AutoPWST-2.0\venv\lib\site-packages\urllib3\request.py", line 74, in request
    return self.request_encode_url(
  File "C:\Users\PWST\Desktop\Automatización\AutoPWST-2.0\AutoPWST-2.0\venv\lib\site-packages\urllib3\request.py", line 96, in request_encode_url
    return self.urlopen(method, url, **extra_kw)
  File "C:\Users\PWST\Desktop\Automatización\AutoPWST-2.0\AutoPWST-2.0\venv\lib\site-packages\urllib3\poolmanager.py", line 376, in urlopen
    response = conn.urlopen(method, u.request_uri, **kw)
  File "C:\Users\PWST\Desktop\Automatización\AutoPWST-2.0\AutoPWST-2.0\venv\lib\site-packages\urllib3\connectionpool.py", line 813, in urlopen
    return self.urlopen(
  File "C:\Users\PWST\Desktop\Automatización\AutoPWST-2.0\AutoPWST-2.0\venv\lib\site-packages\urllib3\connectionpool.py", line 813, in urlopen
    return self.urlopen(
  File "C:\Users\PWST\Desktop\Automatización\AutoPWST-2.0\AutoPWST-2.0\venv\lib\site-packages\urllib3\connectionpool.py", line 813, in urlopen
    return self.urlopen(
  File "C:\Users\PWST\Desktop\Automatización\AutoPWST-2.0\AutoPWST-2.0\venv\lib\site-packages\urllib3\connectionpool.py", line 785, in urlopen
    retries = retries.increment(
  File "C:\Users\PWST\Desktop\Automatización\AutoPWST-2.0\AutoPWST-2.0\venv\lib\site-packages\urllib3\util\retry.py", line 592, in increment
    raise MaxRetryError(_pool, url, error or ResponseError(cause))
urllib3.exceptions.MaxRetryError: HTTPConnectionPool(host='localhost', port=60946): Max retries exceeded with url: /session/f095f59d097b585e77ac5de530293375/screenshot (Caused by NewConnectionError('&lt;urllib3.connection.HTTPConnection object at 0x000001B677B3F520&gt;: Failed to establish a new connection: [WinError 10061] No se puede establecer una conexión ya que el equipo de destino denegó expresamente dicha conexión'))


    </pre>
    </div>
    </td>
    <td align="right">
        <a  href="../../../../img/20220902_16_15_40.png" target="_blank">
            <img src="../../../../img/20220902_16_15_40.png" height="200px" width="400px"/>
        </a>
    </td>
</tr>

<tr id='ft1_8' class='none'>
    <td class='errorCase' width='300px'><div class='testcase'>test_006: Cerrar_Navegador</div></td>
    <td colspan='5' align='left' width='600px'> <!--print 输出框位置-->
    <!--默认收起错误信息 -Findyou
    <button id='btn_ft1_8' type="button"  class="btn btn-primary btn-xs collapsed" data-toggle="collapse" data-target='#div_ft1_8'>Error</button>
    <div id='div_ft1_8' class="collapse">  -->
    <!-- 默认展开错误信息 -Findyou -->
    <button id='btn_ft1_8' type="button"  class="btn btn-primary btn-xs" data-toggle="collapse" data-target='#div_ft1_8'>Error</button>
    <div id='div_ft1_8' class="collapse in">
    <pre style="overflow-y:scroll; overflow-x:hidden;height:200px; width:600px; margin:auto; border:1px solid #e1e1e1;">
    
ft1_8: Traceback (most recent call last):
  File "C:\Users\PWST\Desktop\Automatización\AutoPWST-2.0\AutoPWST-2.0\venv\lib\site-packages\urllib3\connection.py", line 174, in _new_conn
    conn = connection.create_connection(
  File "C:\Users\PWST\Desktop\Automatización\AutoPWST-2.0\AutoPWST-2.0\venv\lib\site-packages\urllib3\util\connection.py", line 95, in create_connection
    raise err
  File "C:\Users\PWST\Desktop\Automatización\AutoPWST-2.0\AutoPWST-2.0\venv\lib\site-packages\urllib3\util\connection.py", line 85, in create_connection
    sock.connect(sa)
ConnectionRefusedError: [WinError 10061] No se puede establecer una conexión ya que el equipo de destino denegó expresamente dicha conexión

During handling of the above exception, another exception occurred:

Traceback (most recent call last):
  File "C:\Users\PWST\Desktop\Automatización\AutoPWST-2.0\AutoPWST-2.0\venv\lib\site-packages\urllib3\connectionpool.py", line 703, in urlopen
    httplib_response = self._make_request(
  File "C:\Users\PWST\Desktop\Automatización\AutoPWST-2.0\AutoPWST-2.0\venv\lib\site-packages\urllib3\connectionpool.py", line 398, in _make_request
    conn.request(method, url, **httplib_request_kw)
  File "C:\Users\PWST\Desktop\Automatización\AutoPWST-2.0\AutoPWST-2.0\venv\lib\site-packages\urllib3\connection.py", line 239, in request
    super(HTTPConnection, self).request(method, url, body=body, headers=headers)
  File "C:\Users\PWST\AppData\Local\Programs\Python\Python310\lib\http\client.py", line 1282, in request
    self._send_request(method, url, body, headers, encode_chunked)
  File "C:\Users\PWST\AppData\Local\Programs\Python\Python310\lib\http\client.py", line 1328, in _send_request
    self.endheaders(body, encode_chunked=encode_chunked)
  File "C:\Users\PWST\AppData\Local\Programs\Python\Python310\lib\http\client.py", line 1277, in endheaders
    self._send_output(message_body, encode_chunked=encode_chunked)
  File "C:\Users\PWST\AppData\Local\Programs\Python\Python310\lib\http\client.py", line 1037, in _send_output
    self.send(msg)
  File "C:\Users\PWST\AppData\Local\Programs\Python\Python310\lib\http\client.py", line 975, in send
    self.connect()
  File "C:\Users\PWST\Desktop\Automatización\AutoPWST-2.0\AutoPWST-2.0\venv\lib\site-packages\urllib3\connection.py", line 205, in connect
    conn = self._new_conn()
  File "C:\Users\PWST\Desktop\Automatización\AutoPWST-2.0\AutoPWST-2.0\venv\lib\site-packages\urllib3\connection.py", line 186, in _new_conn
    raise NewConnectionError(
urllib3.exceptions.NewConnectionError: &lt;urllib3.connection.HTTPConnection object at 0x000001B677B3F460&gt;: Failed to establish a new connection: [WinError 10061] No se puede establecer una conexión ya que el equipo de destino denegó expresamente dicha conexión

During handling of the above exception, another exception occurred:

Traceback (most recent call last):
  File "C:\xampp\htdocs\versiones\automatizaciones\AutoPWST\02AC\testCase\AutorizacionCredito2.py", line 62, in test_006
    self.driver.close()
  File "C:\Users\PWST\Desktop\Automatización\AutoPWST-2.0\AutoPWST-2.0\venv\lib\site-packages\selenium\webdriver\remote\webdriver.py", line 552, in close
    self.execute(Command.CLOSE)
  File "C:\Users\PWST\Desktop\Automatización\AutoPWST-2.0\AutoPWST-2.0\venv\lib\site-packages\selenium\webdriver\remote\webdriver.py", line 433, in execute
    response = self.command_executor.execute(driver_command, params)
  File "C:\Users\PWST\Desktop\Automatización\AutoPWST-2.0\AutoPWST-2.0\venv\lib\site-packages\selenium\webdriver\remote\remote_connection.py", line 344, in execute
    return self._request(command_info[0], url, body=data)
  File "C:\Users\PWST\Desktop\Automatización\AutoPWST-2.0\AutoPWST-2.0\venv\lib\site-packages\selenium\webdriver\remote\remote_connection.py", line 366, in _request
    response = self._conn.request(method, url, body=body, headers=headers)
  File "C:\Users\PWST\Desktop\Automatización\AutoPWST-2.0\AutoPWST-2.0\venv\lib\site-packages\urllib3\request.py", line 74, in request
    return self.request_encode_url(
  File "C:\Users\PWST\Desktop\Automatización\AutoPWST-2.0\AutoPWST-2.0\venv\lib\site-packages\urllib3\request.py", line 96, in request_encode_url
    return self.urlopen(method, url, **extra_kw)
  File "C:\Users\PWST\Desktop\Automatización\AutoPWST-2.0\AutoPWST-2.0\venv\lib\site-packages\urllib3\poolmanager.py", line 376, in urlopen
    response = conn.urlopen(method, u.request_uri, **kw)
  File "C:\Users\PWST\Desktop\Automatización\AutoPWST-2.0\AutoPWST-2.0\venv\lib\site-packages\urllib3\connectionpool.py", line 813, in urlopen
    return self.urlopen(
  File "C:\Users\PWST\Desktop\Automatización\AutoPWST-2.0\AutoPWST-2.0\venv\lib\site-packages\urllib3\connectionpool.py", line 813, in urlopen
    return self.urlopen(
  File "C:\Users\PWST\Desktop\Automatización\AutoPWST-2.0\AutoPWST-2.0\venv\lib\site-packages\urllib3\connectionpool.py", line 813, in urlopen
    return self.urlopen(
  File "C:\Users\PWST\Desktop\Automatización\AutoPWST-2.0\AutoPWST-2.0\venv\lib\site-packages\urllib3\connectionpool.py", line 785, in urlopen
    retries = retries.increment(
  File "C:\Users\PWST\Desktop\Automatización\AutoPWST-2.0\AutoPWST-2.0\venv\lib\site-packages\urllib3\util\retry.py", line 592, in increment
    raise MaxRetryError(_pool, url, error or ResponseError(cause))
urllib3.exceptions.MaxRetryError: HTTPConnectionPool(host='localhost', port=60946): Max retries exceeded with url: /session/f095f59d097b585e77ac5de530293375/window (Caused by NewConnectionError('&lt;urllib3.connection.HTTPConnection object at 0x000001B677B3F460&gt;: Failed to establish a new connection: [WinError 10061] No se puede establecer una conexión ya que el equipo de destino denegó expresamente dicha conexión'))


    </pre>
    </div>
    </td>
    <td align="right">
        <a hidden="hidden" href="" target="_blank">
            <img src="" height="200px" width="400px"/>
        </a>
    </td>
</tr>

<tr id='total_row' class="text-center active">
    <td>Caso de prueba</td>
    <td>8</td>
    <td>3</td>
    <td>0</td>
    <td>5</td>
    <td>Taza de resultado：37.50%</td>
    <td> <a href="" target="_blank"></a></td>
</tr>
</table>

<div id='ending'> </div>
    <div style=" position:fixed;right:50px; bottom:30px; width:20px; height:20px;cursor:pointer">
    <a href="#"><span class="glyphicon glyphicon-eject" style = "font-size:30px;" aria-hidden="true">
    </span></a></div>
    
</body>
</html>
