<?xml version="1.0" encoding="UTF-8"?>
<!DOCTYPE html >
<html xmlns="http://www.w3.org/1999/xhtml">
<head>
    <title>Reporte de pruebas</title>
    <meta name="generator" content="HTMLTestRunner 0.8.2.1"/>
    <meta http-equiv="Content-Type" content="text/html; charset=UTF-8"/>
    <link href="https://libs.baidu.com/bootstrap/3.0.3/css/bootstrap.min.css" rel="stylesheet">
    <script src="https://libs.baidu.com/jquery/2.0.0/jquery.min.js"></script>
    <script src="https://libs.baidu.com/bootstrap/3.0.3/js/bootstrap.min.js"></script>
    
<style type="text/css" media="screen">
@import url("https://fonts.googleapis.com/css2?family=Poppins:wght@400;500;600&display=swap");
    :root{
        --body-font: 'Poppins', sans-serif;

    }
    body{
        margin: var(--header-height) 0 0 0;
        padding: 1rem 1rem 0;
        font-family: var(--body-font);
        background-color: #F9F6FD;
    }    
    .container{
        background-color: white;
        border-radius: 3%;
    }
    .imagenpwst img{
        position:static;
        right: 4%;
        padding-top: 5%;
    }

/* -- report ------------------------------------------------------------------------ */
#total_row  { font-weight: bold; }
.passCase   { color: #5cb85c; }
.failCase   { color: #d9534f; font-weight: bold; }
.errorCase  { color: #f0ad4e; font-weight: bold; }
.hiddenRow  { display: none; }
.testcase   { margin-left: 2em; }
</style>

</head>
<body >
<div class="imagenpwst">
    <img src="https://i.postimg.cc/g2fdS2VC/Recurso-jpg.jpg"width="320"  align="right" >
</div>    
<script language="javascript" type="text/javascript">
output_list = Array();
/*level 
0:Summary //all hiddenRow
1:Failed  //pt hiddenRow, ft none
2:Pass    //pt none, ft hiddenRow
3:All     //pt none, ft none
4:Error  
*/
function showCase(level) {
    trs = document.getElementsByTagName("tr");
    for (var i = 0; i < trs.length; i++) {
        tr = trs[i];
        id = tr.id;
        if (id.substr(0,2) == 'ft') {
            if (level == 2 || level == 0 ) {
                tr.className = 'hiddenRow';
            }
            else {
                tr.className = 'Hola';
            }
        }
        if (id.substr(0,2) == 'pt') {
            if (level < 2 || level ==4) {
                tr.className = 'hiddenRow';
            }
            else {
                tr.className = '';
            }
        }
    }
    detail_class=document.getElementsByClassName('detail');
    //console.log(detail_class.length)
    if (level == 3) {
        for (var i = 0; i < detail_class.length; i++){
            detail_class[i].innerHTML="Ver"
        }
    }
    else{
            for (var i = 0; i < detail_class.length; i++){
            detail_class[i].innerHTML="Ocultar"
        }
    }
}
function showClassDetail(cid, count) {
    var id_list = Array(count);
    var toHide = 1;
    for (var i = 0; i < count; i++) {

        tid0 = 't' + cid.substr(1) + '_' + (i+1);
        tid = 'f' + tid0;
        tr = document.getElementById(tid);
        if (!tr) {
            tid = 'p' + tid0;
            tr = document.getElementById(tid);
        }
        id_list[i] = tid;
        if (tr.className) {
            toHide = 0;
        }
    }
    for (var i = 0; i < count; i++) {
        tid = id_list[i];

        if (toHide) {
            document.getElementById(tid).className = 'hiddenRow';
            document.getElementById(cid).innerText = "Ver"
        }
        else {
            document.getElementById(tid).className = '';
            document.getElementById(cid).innerText = "Ocultar"
        }
    }
}
function html_escape(s) {
    s = s.replace(/&/g,'&');
    s = s.replace(/</g,'<');
    s = s.replace(/>/g,'>');
    return s;
}
</script>
<div class='heading'>
<h2 style="font-family: Microsoft YaHei">Reporte de pruebas</h4>
<p class='attribute'><strong>Desarrollado por : </strong> Area de Testing PWST</p>
<p class='attribute'><strong>Fecha y hora de inicio : </strong> 2022-12-26 12:38:41</p>
<p class='attribute'><strong>Duracion : </strong> 0:05:18.482475</p>
<p class='attribute'><strong>Resultado : </strong> Total 8，Errores 8 ，Taza de resultado 0.00%</p>

<h3 class='description'>Detalles</h3>
</div>


<p id='show_detail_line'>
<a class="btn btn-primary" href='javascript:showCase(0)'>Resumen 0.00% </a>
<a class="btn btn-warning" href='javascript:showCase(4)'>Errores 8 </a>
<a class="btn btn-danger" href='javascript:showCase(1)'>Fallidos 0 </a>
<a class="btn btn-success" href='javascript:showCase(2)'>Correctos 0 </a>
<a class="btn btn-info" href='javascript:showCase(3)'>Test realizados 8 </a>
</p>
<table id='result_table' class="table table-condensed table-bordered table-hover">
<colgroup>
<col align='left' />
<col align='right' />
<col align='right' />
<col align='right' />
<col align='right' />
<col align='right' />
<col align='right' />
</colgroup>
<tr id='header_row' class="text-center success" style="font-weight: bold;font-size: 14px;">
    <td>Caso de Prueba</td>
    <td>Total</td>
    <td>Correctos</td>
    <td>Fallido</td>
    <td>Error</td>
    <td>Detalles</td>
    <td>Captura del error</td>
</tr>

<tr class='errorClass warning'>
    <td>formasdepago.Test: Escenario 1 de Autorizaciones de Credito</td>
    <td class="text-center">8</td>
    <td class="text-center">0</td>
    <td class="text-center">0</td>
    <td class="text-center">8</td>
    <td class="text-center"><a href="javascript:showClassDetail('c1',8)" class="detail" id='c1'>Detalles</a></td>
    <td class="text-center"></td>
</tr>

<tr id='ft1_1' class='none'>
    <td class='errorCase' width='300px'><div class='testcase'>test</div></td>
    <td colspan='5' align='left' width='600px'> <!--print 输出框位置-->
    <!--默认收起错误信息 -Findyou
    <button id='btn_ft1_1' type="button"  class="btn btn-primary btn-xs collapsed" data-toggle="collapse" data-target='#div_ft1_1'>Error</button>
    <div id='div_ft1_1' class="collapse">  -->
    <!-- 默认展开错误信息 -Findyou -->
    <button id='btn_ft1_1' type="button"  class="btn btn-primary btn-xs" data-toggle="collapse" data-target='#div_ft1_1'>Error</button>
    <div id='div_ft1_1' class="collapse in">
    <pre style="overflow-y:scroll; overflow-x:hidden;height:200px; width:600px; margin:auto; border:1px solid #e1e1e1;">
    
ft1_1: 2022-12-26 12:38:43,228 - root - INFO -  Se abre el chrome
Traceback (most recent call last):
  File "C:\Users\pwst\AppData\Local\Programs\Python\Python311\Lib\site-packages\urllib3\connectionpool.py", line 703, in urlopen
    httplib_response = self._make_request(
                       ^^^^^^^^^^^^^^^^^^^
  File "C:\Users\pwst\AppData\Local\Programs\Python\Python311\Lib\site-packages\urllib3\connectionpool.py", line 449, in _make_request
    six.raise_from(e, None)
  File "&lt;string&gt;", line 3, in raise_from
  File "C:\Users\pwst\AppData\Local\Programs\Python\Python311\Lib\site-packages\urllib3\connectionpool.py", line 444, in _make_request
    httplib_response = conn.getresponse()
                       ^^^^^^^^^^^^^^^^^^
  File "C:\Users\pwst\AppData\Local\Programs\Python\Python311\Lib\http\client.py", line 1374, in getresponse
    response.begin()
  File "C:\Users\pwst\AppData\Local\Programs\Python\Python311\Lib\http\client.py", line 318, in begin
    version, status, reason = self._read_status()
                              ^^^^^^^^^^^^^^^^^^^
  File "C:\Users\pwst\AppData\Local\Programs\Python\Python311\Lib\http\client.py", line 279, in _read_status
    line = str(self.fp.readline(_MAXLINE + 1), "iso-8859-1")
               ^^^^^^^^^^^^^^^^^^^^^^^^^^^^^^
  File "C:\Users\pwst\AppData\Local\Programs\Python\Python311\Lib\socket.py", line 706, in readinto
    return self._sock.recv_into(b)
           ^^^^^^^^^^^^^^^^^^^^^^^
ConnectionResetError: [WinError 10054] Se ha forzado la interrupción de una conexión existente por el host remoto

During handling of the above exception, another exception occurred:

Traceback (most recent call last):
  File "C:\xampp\htdocs\Versiones\automatizaciones\AutoPWST\02FDP\testCase\formasdepago.py", line 27, in test
    self.driver.get(configgnral.URL)
  File "C:\Users\pwst\AppData\Local\Programs\Python\Python311\Lib\site-packages\selenium\webdriver\remote\webdriver.py", line 455, in get
    self.execute(Command.GET, {"url": url})
  File "C:\Users\pwst\AppData\Local\Programs\Python\Python311\Lib\site-packages\selenium\webdriver\remote\webdriver.py", line 442, in execute
    response = self.command_executor.execute(driver_command, params)
               ^^^^^^^^^^^^^^^^^^^^^^^^^^^^^^^^^^^^^^^^^^^^^^^^^^^^^
  File "C:\Users\pwst\AppData\Local\Programs\Python\Python311\Lib\site-packages\selenium\webdriver\remote\remote_connection.py", line 294, in execute
    return self._request(command_info[0], url, body=data)
           ^^^^^^^^^^^^^^^^^^^^^^^^^^^^^^^^^^^^^^^^^^^^^^
  File "C:\Users\pwst\AppData\Local\Programs\Python\Python311\Lib\site-packages\selenium\webdriver\remote\remote_connection.py", line 316, in _request
    response = self._conn.request(method, url, body=body, headers=headers)
               ^^^^^^^^^^^^^^^^^^^^^^^^^^^^^^^^^^^^^^^^^^^^^^^^^^^^^^^^^^^
  File "C:\Users\pwst\AppData\Local\Programs\Python\Python311\Lib\site-packages\urllib3\request.py", line 78, in request
    return self.request_encode_body(
           ^^^^^^^^^^^^^^^^^^^^^^^^^
  File "C:\Users\pwst\AppData\Local\Programs\Python\Python311\Lib\site-packages\urllib3\request.py", line 170, in request_encode_body
    return self.urlopen(method, url, **extra_kw)
           ^^^^^^^^^^^^^^^^^^^^^^^^^^^^^^^^^^^^^
  File "C:\Users\pwst\AppData\Local\Programs\Python\Python311\Lib\site-packages\urllib3\poolmanager.py", line 376, in urlopen
    response = conn.urlopen(method, u.request_uri, **kw)
               ^^^^^^^^^^^^^^^^^^^^^^^^^^^^^^^^^^^^^^^^^
  File "C:\Users\pwst\AppData\Local\Programs\Python\Python311\Lib\site-packages\urllib3\connectionpool.py", line 787, in urlopen
    retries = retries.increment(
              ^^^^^^^^^^^^^^^^^^
  File "C:\Users\pwst\AppData\Local\Programs\Python\Python311\Lib\site-packages\urllib3\util\retry.py", line 550, in increment
    raise six.reraise(type(error), error, _stacktrace)
          ^^^^^^^^^^^^^^^^^^^^^^^^^^^^^^^^^^^^^^^^^^^^
  File "C:\Users\pwst\AppData\Local\Programs\Python\Python311\Lib\site-packages\urllib3\packages\six.py", line 769, in reraise
    raise value.with_traceback(tb)
  File "C:\Users\pwst\AppData\Local\Programs\Python\Python311\Lib\site-packages\urllib3\connectionpool.py", line 703, in urlopen
    httplib_response = self._make_request(
                       ^^^^^^^^^^^^^^^^^^^
  File "C:\Users\pwst\AppData\Local\Programs\Python\Python311\Lib\site-packages\urllib3\connectionpool.py", line 449, in _make_request
    six.raise_from(e, None)
  File "&lt;string&gt;", line 3, in raise_from
  File "C:\Users\pwst\AppData\Local\Programs\Python\Python311\Lib\site-packages\urllib3\connectionpool.py", line 444, in _make_request
    httplib_response = conn.getresponse()
                       ^^^^^^^^^^^^^^^^^^
  File "C:\Users\pwst\AppData\Local\Programs\Python\Python311\Lib\http\client.py", line 1374, in getresponse
    response.begin()
  File "C:\Users\pwst\AppData\Local\Programs\Python\Python311\Lib\http\client.py", line 318, in begin
    version, status, reason = self._read_status()
                              ^^^^^^^^^^^^^^^^^^^
  File "C:\Users\pwst\AppData\Local\Programs\Python\Python311\Lib\http\client.py", line 279, in _read_status
    line = str(self.fp.readline(_MAXLINE + 1), "iso-8859-1")
               ^^^^^^^^^^^^^^^^^^^^^^^^^^^^^^
  File "C:\Users\pwst\AppData\Local\Programs\Python\Python311\Lib\socket.py", line 706, in readinto
    return self._sock.recv_into(b)
           ^^^^^^^^^^^^^^^^^^^^^^^
urllib3.exceptions.ProtocolError: ('Connection aborted.', ConnectionResetError(10054, 'Se ha forzado la interrupción de una conexión existente por el host remoto', None, 10054, None))


    </pre>
    </div>
    </td>
    <td align="right">
        <a hidden="hidden" href="" target="_blank">
            <img src="" height="200px" width="400px"/>
        </a>
    </td>
</tr>

<tr id='ft1_2' class='none'>
    <td class='errorCase' width='300px'><div class='testcase'>test_000: Ingresa a la base de datos</div></td>
    <td colspan='5' align='left' width='600px'> <!--print 输出框位置-->
    <!--默认收起错误信息 -Findyou
    <button id='btn_ft1_2' type="button"  class="btn btn-primary btn-xs collapsed" data-toggle="collapse" data-target='#div_ft1_2'>Error</button>
    <div id='div_ft1_2' class="collapse">  -->
    <!-- 默认展开错误信息 -Findyou -->
    <button id='btn_ft1_2' type="button"  class="btn btn-primary btn-xs" data-toggle="collapse" data-target='#div_ft1_2'>Error</button>
    <div id='div_ft1_2' class="collapse in">
    <pre style="overflow-y:scroll; overflow-x:hidden;height:200px; width:600px; margin:auto; border:1px solid #e1e1e1;">
    
ft1_2: 2022-12-26 12:40:43,725 - root - ERROR - No se pudo encontrar el campo para ingresar el usuario, revise si el xpath sigue siendo el mismo, para mas detalles del error consulte el reporte
2022-12-26 12:40:43,727 - root - INFO -  Captura: C:\xampp\htdocs\Versiones\automatizaciones\AutoPWST\02FDP\report\img  screen：20221226_12_40_43.png
Traceback (most recent call last):
  File "C:\Users\pwst\AppData\Local\Programs\Python\Python311\Lib\site-packages\urllib3\connection.py", line 174, in _new_conn
    conn = connection.create_connection(
           ^^^^^^^^^^^^^^^^^^^^^^^^^^^^^
  File "C:\Users\pwst\AppData\Local\Programs\Python\Python311\Lib\site-packages\urllib3\util\connection.py", line 95, in create_connection
    raise err
  File "C:\Users\pwst\AppData\Local\Programs\Python\Python311\Lib\site-packages\urllib3\util\connection.py", line 85, in create_connection
    sock.connect(sa)
ConnectionRefusedError: [WinError 10061] No se puede establecer una conexión ya que el equipo de destino denegó expresamente dicha conexión

During handling of the above exception, another exception occurred:

Traceback (most recent call last):
  File "C:\Users\pwst\AppData\Local\Programs\Python\Python311\Lib\site-packages\urllib3\connectionpool.py", line 703, in urlopen
    httplib_response = self._make_request(
                       ^^^^^^^^^^^^^^^^^^^
  File "C:\Users\pwst\AppData\Local\Programs\Python\Python311\Lib\site-packages\urllib3\connectionpool.py", line 398, in _make_request
    conn.request(method, url, **httplib_request_kw)
  File "C:\Users\pwst\AppData\Local\Programs\Python\Python311\Lib\site-packages\urllib3\connection.py", line 239, in request
    super(HTTPConnection, self).request(method, url, body=body, headers=headers)
  File "C:\Users\pwst\AppData\Local\Programs\Python\Python311\Lib\http\client.py", line 1282, in request
    self._send_request(method, url, body, headers, encode_chunked)
  File "C:\Users\pwst\AppData\Local\Programs\Python\Python311\Lib\http\client.py", line 1328, in _send_request
    self.endheaders(body, encode_chunked=encode_chunked)
  File "C:\Users\pwst\AppData\Local\Programs\Python\Python311\Lib\http\client.py", line 1277, in endheaders
    self._send_output(message_body, encode_chunked=encode_chunked)
  File "C:\Users\pwst\AppData\Local\Programs\Python\Python311\Lib\http\client.py", line 1037, in _send_output
    self.send(msg)
  File "C:\Users\pwst\AppData\Local\Programs\Python\Python311\Lib\http\client.py", line 975, in send
    self.connect()
  File "C:\Users\pwst\AppData\Local\Programs\Python\Python311\Lib\site-packages\urllib3\connection.py", line 205, in connect
    conn = self._new_conn()
           ^^^^^^^^^^^^^^^^
  File "C:\Users\pwst\AppData\Local\Programs\Python\Python311\Lib\site-packages\urllib3\connection.py", line 186, in _new_conn
    raise NewConnectionError(
urllib3.exceptions.NewConnectionError: &lt;urllib3.connection.HTTPConnection object at 0x000001BB647FBDD0&gt;: Failed to establish a new connection: [WinError 10061] No se puede establecer una conexión ya que el equipo de destino denegó expresamente dicha conexión

During handling of the above exception, another exception occurred:

Traceback (most recent call last):
  File "C:/xampp/htdocs/versiones/automatizaciones/AutoPWST/ingresologin.py", line 26, in ingresologin
    Usuario = self.wait.until(conditions.visibility((By.XPATH, configgnral.id_usuario)))
              ^^^^^^^^^^^^^^^^^^^^^^^^^^^^^^^^^^^^^^^^^^^^^^^^^^^^^^^^^^^^^^^^^^^^^^^^^^
  File "C:\Users\pwst\AppData\Local\Programs\Python\Python311\Lib\site-packages\selenium\webdriver\support\wait.py", line 86, in until
    value = method(self._driver)
            ^^^^^^^^^^^^^^^^^^^^
  File "C:\Users\pwst\AppData\Local\Programs\Python\Python311\Lib\site-packages\selenium\webdriver\support\expected_conditions.py", line 125, in _predicate
    return _element_if_visible(driver.find_element(*locator))
                               ^^^^^^^^^^^^^^^^^^^^^^^^^^^^^
  File "C:\Users\pwst\AppData\Local\Programs\Python\Python311\Lib\site-packages\selenium\webdriver\remote\webdriver.py", line 861, in find_element
    return self.execute(Command.FIND_ELEMENT, {"using": by, "value": value})["value"]
           ^^^^^^^^^^^^^^^^^^^^^^^^^^^^^^^^^^^^^^^^^^^^^^^^^^^^^^^^^^^^^^^^^
  File "C:\Users\pwst\AppData\Local\Programs\Python\Python311\Lib\site-packages\selenium\webdriver\remote\webdriver.py", line 442, in execute
    response = self.command_executor.execute(driver_command, params)
               ^^^^^^^^^^^^^^^^^^^^^^^^^^^^^^^^^^^^^^^^^^^^^^^^^^^^^
  File "C:\Users\pwst\AppData\Local\Programs\Python\Python311\Lib\site-packages\selenium\webdriver\remote\remote_connection.py", line 294, in execute
    return self._request(command_info[0], url, body=data)
           ^^^^^^^^^^^^^^^^^^^^^^^^^^^^^^^^^^^^^^^^^^^^^^
  File "C:\Users\pwst\AppData\Local\Programs\Python\Python311\Lib\site-packages\selenium\webdriver\remote\remote_connection.py", line 316, in _request
    response = self._conn.request(method, url, body=body, headers=headers)
               ^^^^^^^^^^^^^^^^^^^^^^^^^^^^^^^^^^^^^^^^^^^^^^^^^^^^^^^^^^^
  File "C:\Users\pwst\AppData\Local\Programs\Python\Python311\Lib\site-packages\urllib3\request.py", line 78, in request
    return self.request_encode_body(
           ^^^^^^^^^^^^^^^^^^^^^^^^^
  File "C:\Users\pwst\AppData\Local\Programs\Python\Python311\Lib\site-packages\urllib3\request.py", line 170, in request_encode_body
    return self.urlopen(method, url, **extra_kw)
           ^^^^^^^^^^^^^^^^^^^^^^^^^^^^^^^^^^^^^
  File "C:\Users\pwst\AppData\Local\Programs\Python\Python311\Lib\site-packages\urllib3\poolmanager.py", line 376, in urlopen
    response = conn.urlopen(method, u.request_uri, **kw)
               ^^^^^^^^^^^^^^^^^^^^^^^^^^^^^^^^^^^^^^^^^
  File "C:\Users\pwst\AppData\Local\Programs\Python\Python311\Lib\site-packages\urllib3\connectionpool.py", line 815, in urlopen
    return self.urlopen(
           ^^^^^^^^^^^^^
  File "C:\Users\pwst\AppData\Local\Programs\Python\Python311\Lib\site-packages\urllib3\connectionpool.py", line 815, in urlopen
    return self.urlopen(
           ^^^^^^^^^^^^^
  File "C:\Users\pwst\AppData\Local\Programs\Python\Python311\Lib\site-packages\urllib3\connectionpool.py", line 815, in urlopen
    return self.urlopen(
           ^^^^^^^^^^^^^
  File "C:\Users\pwst\AppData\Local\Programs\Python\Python311\Lib\site-packages\urllib3\connectionpool.py", line 787, in urlopen
    retries = retries.increment(
              ^^^^^^^^^^^^^^^^^^
  File "C:\Users\pwst\AppData\Local\Programs\Python\Python311\Lib\site-packages\urllib3\util\retry.py", line 592, in increment
    raise MaxRetryError(_pool, url, error or ResponseError(cause))
urllib3.exceptions.MaxRetryError: HTTPConnectionPool(host='localhost', port=53315): Max retries exceeded with url: /session/087d1ef2366c9ea12ffcc182873be34a/element (Caused by NewConnectionError('&lt;urllib3.connection.HTTPConnection object at 0x000001BB647FBDD0&gt;: Failed to establish a new connection: [WinError 10061] No se puede establecer una conexión ya que el equipo de destino denegó expresamente dicha conexión'))

During handling of the above exception, another exception occurred:

Traceback (most recent call last):
  File "C:\Users\pwst\AppData\Local\Programs\Python\Python311\Lib\site-packages\urllib3\connection.py", line 174, in _new_conn
    conn = connection.create_connection(
           ^^^^^^^^^^^^^^^^^^^^^^^^^^^^^
  File "C:\Users\pwst\AppData\Local\Programs\Python\Python311\Lib\site-packages\urllib3\util\connection.py", line 95, in create_connection
    raise err
  File "C:\Users\pwst\AppData\Local\Programs\Python\Python311\Lib\site-packages\urllib3\util\connection.py", line 85, in create_connection
    sock.connect(sa)
ConnectionRefusedError: [WinError 10061] No se puede establecer una conexión ya que el equipo de destino denegó expresamente dicha conexión

During handling of the above exception, another exception occurred:

Traceback (most recent call last):
  File "C:\Users\pwst\AppData\Local\Programs\Python\Python311\Lib\site-packages\urllib3\connectionpool.py", line 703, in urlopen
    httplib_response = self._make_request(
                       ^^^^^^^^^^^^^^^^^^^
  File "C:\Users\pwst\AppData\Local\Programs\Python\Python311\Lib\site-packages\urllib3\connectionpool.py", line 398, in _make_request
    conn.request(method, url, **httplib_request_kw)
  File "C:\Users\pwst\AppData\Local\Programs\Python\Python311\Lib\site-packages\urllib3\connection.py", line 239, in request
    super(HTTPConnection, self).request(method, url, body=body, headers=headers)
  File "C:\Users\pwst\AppData\Local\Programs\Python\Python311\Lib\http\client.py", line 1282, in request
    self._send_request(method, url, body, headers, encode_chunked)
  File "C:\Users\pwst\AppData\Local\Programs\Python\Python311\Lib\http\client.py", line 1328, in _send_request
    self.endheaders(body, encode_chunked=encode_chunked)
  File "C:\Users\pwst\AppData\Local\Programs\Python\Python311\Lib\http\client.py", line 1277, in endheaders
    self._send_output(message_body, encode_chunked=encode_chunked)
  File "C:\Users\pwst\AppData\Local\Programs\Python\Python311\Lib\http\client.py", line 1037, in _send_output
    self.send(msg)
  File "C:\Users\pwst\AppData\Local\Programs\Python\Python311\Lib\http\client.py", line 975, in send
    self.connect()
  File "C:\Users\pwst\AppData\Local\Programs\Python\Python311\Lib\site-packages\urllib3\connection.py", line 205, in connect
    conn = self._new_conn()
           ^^^^^^^^^^^^^^^^
  File "C:\Users\pwst\AppData\Local\Programs\Python\Python311\Lib\site-packages\urllib3\connection.py", line 186, in _new_conn
    raise NewConnectionError(
urllib3.exceptions.NewConnectionError: &lt;urllib3.connection.HTTPConnection object at 0x000001BB6482EED0&gt;: Failed to establish a new connection: [WinError 10061] No se puede establecer una conexión ya que el equipo de destino denegó expresamente dicha conexión

During handling of the above exception, another exception occurred:

Traceback (most recent call last):
  File "C:\xampp\htdocs\Versiones\automatizaciones\AutoPWST\02FDP\testCase\formasdepago.py", line 38, in test_000
    return ingresologin.ingresologin(self)
           ^^^^^^^^^^^^^^^^^^^^^^^^^^^^^^^
  File "C:/xampp/htdocs/versiones/automatizaciones/AutoPWST/ingresologin.py", line 35, in ingresologin
    self.driver.get_screenshot_as_file(img_name)
  File "C:\Users\pwst\AppData\Local\Programs\Python\Python311\Lib\site-packages\selenium\webdriver\remote\webdriver.py", line 929, in get_screenshot_as_file
    png = self.get_screenshot_as_png()
          ^^^^^^^^^^^^^^^^^^^^^^^^^^^^
  File "C:\Users\pwst\AppData\Local\Programs\Python\Python311\Lib\site-packages\selenium\webdriver\remote\webdriver.py", line 965, in get_screenshot_as_png
    return b64decode(self.get_screenshot_as_base64().encode("ascii"))
                     ^^^^^^^^^^^^^^^^^^^^^^^^^^^^^^^
  File "C:\Users\pwst\AppData\Local\Programs\Python\Python311\Lib\site-packages\selenium\webdriver\remote\webdriver.py", line 977, in get_screenshot_as_base64
    return self.execute(Command.SCREENSHOT)["value"]
           ^^^^^^^^^^^^^^^^^^^^^^^^^^^^^^^^
  File "C:\Users\pwst\AppData\Local\Programs\Python\Python311\Lib\site-packages\selenium\webdriver\remote\webdriver.py", line 442, in execute
    response = self.command_executor.execute(driver_command, params)
               ^^^^^^^^^^^^^^^^^^^^^^^^^^^^^^^^^^^^^^^^^^^^^^^^^^^^^
  File "C:\Users\pwst\AppData\Local\Programs\Python\Python311\Lib\site-packages\selenium\webdriver\remote\remote_connection.py", line 294, in execute
    return self._request(command_info[0], url, body=data)
           ^^^^^^^^^^^^^^^^^^^^^^^^^^^^^^^^^^^^^^^^^^^^^^
  File "C:\Users\pwst\AppData\Local\Programs\Python\Python311\Lib\site-packages\selenium\webdriver\remote\remote_connection.py", line 316, in _request
    response = self._conn.request(method, url, body=body, headers=headers)
               ^^^^^^^^^^^^^^^^^^^^^^^^^^^^^^^^^^^^^^^^^^^^^^^^^^^^^^^^^^^
  File "C:\Users\pwst\AppData\Local\Programs\Python\Python311\Lib\site-packages\urllib3\request.py", line 74, in request
    return self.request_encode_url(
           ^^^^^^^^^^^^^^^^^^^^^^^^
  File "C:\Users\pwst\AppData\Local\Programs\Python\Python311\Lib\site-packages\urllib3\request.py", line 96, in request_encode_url
    return self.urlopen(method, url, **extra_kw)
           ^^^^^^^^^^^^^^^^^^^^^^^^^^^^^^^^^^^^^
  File "C:\Users\pwst\AppData\Local\Programs\Python\Python311\Lib\site-packages\urllib3\poolmanager.py", line 376, in urlopen
    response = conn.urlopen(method, u.request_uri, **kw)
               ^^^^^^^^^^^^^^^^^^^^^^^^^^^^^^^^^^^^^^^^^
  File "C:\Users\pwst\AppData\Local\Programs\Python\Python311\Lib\site-packages\urllib3\connectionpool.py", line 815, in urlopen
    return self.urlopen(
           ^^^^^^^^^^^^^
  File "C:\Users\pwst\AppData\Local\Programs\Python\Python311\Lib\site-packages\urllib3\connectionpool.py", line 815, in urlopen
    return self.urlopen(
           ^^^^^^^^^^^^^
  File "C:\Users\pwst\AppData\Local\Programs\Python\Python311\Lib\site-packages\urllib3\connectionpool.py", line 815, in urlopen
    return self.urlopen(
           ^^^^^^^^^^^^^
  File "C:\Users\pwst\AppData\Local\Programs\Python\Python311\Lib\site-packages\urllib3\connectionpool.py", line 787, in urlopen
    retries = retries.increment(
              ^^^^^^^^^^^^^^^^^^
  File "C:\Users\pwst\AppData\Local\Programs\Python\Python311\Lib\site-packages\urllib3\util\retry.py", line 592, in increment
    raise MaxRetryError(_pool, url, error or ResponseError(cause))
urllib3.exceptions.MaxRetryError: HTTPConnectionPool(host='localhost', port=53315): Max retries exceeded with url: /session/087d1ef2366c9ea12ffcc182873be34a/screenshot (Caused by NewConnectionError('&lt;urllib3.connection.HTTPConnection object at 0x000001BB6482EED0&gt;: Failed to establish a new connection: [WinError 10061] No se puede establecer una conexión ya que el equipo de destino denegó expresamente dicha conexión'))


    </pre>
    </div>
    </td>
    <td align="right">
        <a  href="../../../../img/20221226_12_40_43.png" target="_blank">
            <img src="../../../../img/20221226_12_40_43.png" height="200px" width="400px"/>
        </a>
    </td>
</tr>

<tr id='ft1_3' class='none'>
    <td class='errorCase' width='300px'><div class='testcase'>test_001: Abre menu y ejecuta pantalla</div></td>
    <td colspan='5' align='left' width='600px'> <!--print 输出框位置-->
    <!--默认收起错误信息 -Findyou
    <button id='btn_ft1_3' type="button"  class="btn btn-primary btn-xs collapsed" data-toggle="collapse" data-target='#div_ft1_3'>Error</button>
    <div id='div_ft1_3' class="collapse">  -->
    <!-- 默认展开错误信息 -Findyou -->
    <button id='btn_ft1_3' type="button"  class="btn btn-primary btn-xs" data-toggle="collapse" data-target='#div_ft1_3'>Error</button>
    <div id='div_ft1_3' class="collapse in">
    <pre style="overflow-y:scroll; overflow-x:hidden;height:200px; width:600px; margin:auto; border:1px solid #e1e1e1;">
    
ft1_3: 2022-12-26 12:41:16,493 - root - ERROR - No se pudo encontrar el menu indicado, revise si el xpath sigue siendo el mismo, revise la accion anterior si el xpath es el correcto o el tiempo de la accion
2022-12-26 12:41:16,495 - root - INFO -  Captura: C:\xampp\htdocs\Versiones\automatizaciones\AutoPWST\02FDP\report\img  screen：20221226_12_41_16.png
Traceback (most recent call last):
  File "C:\Users\pwst\AppData\Local\Programs\Python\Python311\Lib\site-packages\urllib3\connection.py", line 174, in _new_conn
    conn = connection.create_connection(
           ^^^^^^^^^^^^^^^^^^^^^^^^^^^^^
  File "C:\Users\pwst\AppData\Local\Programs\Python\Python311\Lib\site-packages\urllib3\util\connection.py", line 95, in create_connection
    raise err
  File "C:\Users\pwst\AppData\Local\Programs\Python\Python311\Lib\site-packages\urllib3\util\connection.py", line 85, in create_connection
    sock.connect(sa)
ConnectionRefusedError: [WinError 10061] No se puede establecer una conexión ya que el equipo de destino denegó expresamente dicha conexión

During handling of the above exception, another exception occurred:

Traceback (most recent call last):
  File "C:\Users\pwst\AppData\Local\Programs\Python\Python311\Lib\site-packages\urllib3\connectionpool.py", line 703, in urlopen
    httplib_response = self._make_request(
                       ^^^^^^^^^^^^^^^^^^^
  File "C:\Users\pwst\AppData\Local\Programs\Python\Python311\Lib\site-packages\urllib3\connectionpool.py", line 398, in _make_request
    conn.request(method, url, **httplib_request_kw)
  File "C:\Users\pwst\AppData\Local\Programs\Python\Python311\Lib\site-packages\urllib3\connection.py", line 239, in request
    super(HTTPConnection, self).request(method, url, body=body, headers=headers)
  File "C:\Users\pwst\AppData\Local\Programs\Python\Python311\Lib\http\client.py", line 1282, in request
    self._send_request(method, url, body, headers, encode_chunked)
  File "C:\Users\pwst\AppData\Local\Programs\Python\Python311\Lib\http\client.py", line 1328, in _send_request
    self.endheaders(body, encode_chunked=encode_chunked)
  File "C:\Users\pwst\AppData\Local\Programs\Python\Python311\Lib\http\client.py", line 1277, in endheaders
    self._send_output(message_body, encode_chunked=encode_chunked)
  File "C:\Users\pwst\AppData\Local\Programs\Python\Python311\Lib\http\client.py", line 1037, in _send_output
    self.send(msg)
  File "C:\Users\pwst\AppData\Local\Programs\Python\Python311\Lib\http\client.py", line 975, in send
    self.connect()
  File "C:\Users\pwst\AppData\Local\Programs\Python\Python311\Lib\site-packages\urllib3\connection.py", line 205, in connect
    conn = self._new_conn()
           ^^^^^^^^^^^^^^^^
  File "C:\Users\pwst\AppData\Local\Programs\Python\Python311\Lib\site-packages\urllib3\connection.py", line 186, in _new_conn
    raise NewConnectionError(
urllib3.exceptions.NewConnectionError: &lt;urllib3.connection.HTTPConnection object at 0x000001BB6483FE50&gt;: Failed to establish a new connection: [WinError 10061] No se puede establecer una conexión ya que el equipo de destino denegó expresamente dicha conexión

During handling of the above exception, another exception occurred:

Traceback (most recent call last):
  File "C:\xampp\htdocs\Versiones\automatizaciones\AutoPWST\02FDP\testCase\ingresopantalla.py", line 21, in ingresopantalla
    Tablas = self.wait.until(conditions.visibility((By.XPATH, "//*[@id='_tablas']")))
             ^^^^^^^^^^^^^^^^^^^^^^^^^^^^^^^^^^^^^^^^^^^^^^^^^^^^^^^^^^^^^^^^^^^^^^^^
  File "C:\Users\pwst\AppData\Local\Programs\Python\Python311\Lib\site-packages\selenium\webdriver\support\wait.py", line 86, in until
    value = method(self._driver)
            ^^^^^^^^^^^^^^^^^^^^
  File "C:\Users\pwst\AppData\Local\Programs\Python\Python311\Lib\site-packages\selenium\webdriver\support\expected_conditions.py", line 125, in _predicate
    return _element_if_visible(driver.find_element(*locator))
                               ^^^^^^^^^^^^^^^^^^^^^^^^^^^^^
  File "C:\Users\pwst\AppData\Local\Programs\Python\Python311\Lib\site-packages\selenium\webdriver\remote\webdriver.py", line 861, in find_element
    return self.execute(Command.FIND_ELEMENT, {"using": by, "value": value})["value"]
           ^^^^^^^^^^^^^^^^^^^^^^^^^^^^^^^^^^^^^^^^^^^^^^^^^^^^^^^^^^^^^^^^^
  File "C:\Users\pwst\AppData\Local\Programs\Python\Python311\Lib\site-packages\selenium\webdriver\remote\webdriver.py", line 442, in execute
    response = self.command_executor.execute(driver_command, params)
               ^^^^^^^^^^^^^^^^^^^^^^^^^^^^^^^^^^^^^^^^^^^^^^^^^^^^^
  File "C:\Users\pwst\AppData\Local\Programs\Python\Python311\Lib\site-packages\selenium\webdriver\remote\remote_connection.py", line 294, in execute
    return self._request(command_info[0], url, body=data)
           ^^^^^^^^^^^^^^^^^^^^^^^^^^^^^^^^^^^^^^^^^^^^^^
  File "C:\Users\pwst\AppData\Local\Programs\Python\Python311\Lib\site-packages\selenium\webdriver\remote\remote_connection.py", line 316, in _request
    response = self._conn.request(method, url, body=body, headers=headers)
               ^^^^^^^^^^^^^^^^^^^^^^^^^^^^^^^^^^^^^^^^^^^^^^^^^^^^^^^^^^^
  File "C:\Users\pwst\AppData\Local\Programs\Python\Python311\Lib\site-packages\urllib3\request.py", line 78, in request
    return self.request_encode_body(
           ^^^^^^^^^^^^^^^^^^^^^^^^^
  File "C:\Users\pwst\AppData\Local\Programs\Python\Python311\Lib\site-packages\urllib3\request.py", line 170, in request_encode_body
    return self.urlopen(method, url, **extra_kw)
           ^^^^^^^^^^^^^^^^^^^^^^^^^^^^^^^^^^^^^
  File "C:\Users\pwst\AppData\Local\Programs\Python\Python311\Lib\site-packages\urllib3\poolmanager.py", line 376, in urlopen
    response = conn.urlopen(method, u.request_uri, **kw)
               ^^^^^^^^^^^^^^^^^^^^^^^^^^^^^^^^^^^^^^^^^
  File "C:\Users\pwst\AppData\Local\Programs\Python\Python311\Lib\site-packages\urllib3\connectionpool.py", line 815, in urlopen
    return self.urlopen(
           ^^^^^^^^^^^^^
  File "C:\Users\pwst\AppData\Local\Programs\Python\Python311\Lib\site-packages\urllib3\connectionpool.py", line 815, in urlopen
    return self.urlopen(
           ^^^^^^^^^^^^^
  File "C:\Users\pwst\AppData\Local\Programs\Python\Python311\Lib\site-packages\urllib3\connectionpool.py", line 815, in urlopen
    return self.urlopen(
           ^^^^^^^^^^^^^
  File "C:\Users\pwst\AppData\Local\Programs\Python\Python311\Lib\site-packages\urllib3\connectionpool.py", line 787, in urlopen
    retries = retries.increment(
              ^^^^^^^^^^^^^^^^^^
  File "C:\Users\pwst\AppData\Local\Programs\Python\Python311\Lib\site-packages\urllib3\util\retry.py", line 592, in increment
    raise MaxRetryError(_pool, url, error or ResponseError(cause))
urllib3.exceptions.MaxRetryError: HTTPConnectionPool(host='localhost', port=53315): Max retries exceeded with url: /session/087d1ef2366c9ea12ffcc182873be34a/element (Caused by NewConnectionError('&lt;urllib3.connection.HTTPConnection object at 0x000001BB6483FE50&gt;: Failed to establish a new connection: [WinError 10061] No se puede establecer una conexión ya que el equipo de destino denegó expresamente dicha conexión'))

During handling of the above exception, another exception occurred:

Traceback (most recent call last):
  File "C:\Users\pwst\AppData\Local\Programs\Python\Python311\Lib\site-packages\urllib3\connection.py", line 174, in _new_conn
    conn = connection.create_connection(
           ^^^^^^^^^^^^^^^^^^^^^^^^^^^^^
  File "C:\Users\pwst\AppData\Local\Programs\Python\Python311\Lib\site-packages\urllib3\util\connection.py", line 95, in create_connection
    raise err
  File "C:\Users\pwst\AppData\Local\Programs\Python\Python311\Lib\site-packages\urllib3\util\connection.py", line 85, in create_connection
    sock.connect(sa)
ConnectionRefusedError: [WinError 10061] No se puede establecer una conexión ya que el equipo de destino denegó expresamente dicha conexión

During handling of the above exception, another exception occurred:

Traceback (most recent call last):
  File "C:\Users\pwst\AppData\Local\Programs\Python\Python311\Lib\site-packages\urllib3\connectionpool.py", line 703, in urlopen
    httplib_response = self._make_request(
                       ^^^^^^^^^^^^^^^^^^^
  File "C:\Users\pwst\AppData\Local\Programs\Python\Python311\Lib\site-packages\urllib3\connectionpool.py", line 398, in _make_request
    conn.request(method, url, **httplib_request_kw)
  File "C:\Users\pwst\AppData\Local\Programs\Python\Python311\Lib\site-packages\urllib3\connection.py", line 239, in request
    super(HTTPConnection, self).request(method, url, body=body, headers=headers)
  File "C:\Users\pwst\AppData\Local\Programs\Python\Python311\Lib\http\client.py", line 1282, in request
    self._send_request(method, url, body, headers, encode_chunked)
  File "C:\Users\pwst\AppData\Local\Programs\Python\Python311\Lib\http\client.py", line 1328, in _send_request
    self.endheaders(body, encode_chunked=encode_chunked)
  File "C:\Users\pwst\AppData\Local\Programs\Python\Python311\Lib\http\client.py", line 1277, in endheaders
    self._send_output(message_body, encode_chunked=encode_chunked)
  File "C:\Users\pwst\AppData\Local\Programs\Python\Python311\Lib\http\client.py", line 1037, in _send_output
    self.send(msg)
  File "C:\Users\pwst\AppData\Local\Programs\Python\Python311\Lib\http\client.py", line 975, in send
    self.connect()
  File "C:\Users\pwst\AppData\Local\Programs\Python\Python311\Lib\site-packages\urllib3\connection.py", line 205, in connect
    conn = self._new_conn()
           ^^^^^^^^^^^^^^^^
  File "C:\Users\pwst\AppData\Local\Programs\Python\Python311\Lib\site-packages\urllib3\connection.py", line 186, in _new_conn
    raise NewConnectionError(
urllib3.exceptions.NewConnectionError: &lt;urllib3.connection.HTTPConnection object at 0x000001BB6482E010&gt;: Failed to establish a new connection: [WinError 10061] No se puede establecer una conexión ya que el equipo de destino denegó expresamente dicha conexión

During handling of the above exception, another exception occurred:

Traceback (most recent call last):
  File "C:\xampp\htdocs\Versiones\automatizaciones\AutoPWST\02FDP\testCase\formasdepago.py", line 44, in test_001
    success = ingresopantalla.ingresopantalla.ingresopantalla(self, conditions, Configuracion)
              ^^^^^^^^^^^^^^^^^^^^^^^^^^^^^^^^^^^^^^^^^^^^^^^^^^^^^^^^^^^^^^^^^^^^^^^^^^^^^^^^
  File "C:\xampp\htdocs\Versiones\automatizaciones\AutoPWST\02FDP\testCase\ingresopantalla.py", line 43, in ingresopantalla
    self.driver.get_screenshot_as_file(img_name)
  File "C:\Users\pwst\AppData\Local\Programs\Python\Python311\Lib\site-packages\selenium\webdriver\remote\webdriver.py", line 929, in get_screenshot_as_file
    png = self.get_screenshot_as_png()
          ^^^^^^^^^^^^^^^^^^^^^^^^^^^^
  File "C:\Users\pwst\AppData\Local\Programs\Python\Python311\Lib\site-packages\selenium\webdriver\remote\webdriver.py", line 965, in get_screenshot_as_png
    return b64decode(self.get_screenshot_as_base64().encode("ascii"))
                     ^^^^^^^^^^^^^^^^^^^^^^^^^^^^^^^
  File "C:\Users\pwst\AppData\Local\Programs\Python\Python311\Lib\site-packages\selenium\webdriver\remote\webdriver.py", line 977, in get_screenshot_as_base64
    return self.execute(Command.SCREENSHOT)["value"]
           ^^^^^^^^^^^^^^^^^^^^^^^^^^^^^^^^
  File "C:\Users\pwst\AppData\Local\Programs\Python\Python311\Lib\site-packages\selenium\webdriver\remote\webdriver.py", line 442, in execute
    response = self.command_executor.execute(driver_command, params)
               ^^^^^^^^^^^^^^^^^^^^^^^^^^^^^^^^^^^^^^^^^^^^^^^^^^^^^
  File "C:\Users\pwst\AppData\Local\Programs\Python\Python311\Lib\site-packages\selenium\webdriver\remote\remote_connection.py", line 294, in execute
    return self._request(command_info[0], url, body=data)
           ^^^^^^^^^^^^^^^^^^^^^^^^^^^^^^^^^^^^^^^^^^^^^^
  File "C:\Users\pwst\AppData\Local\Programs\Python\Python311\Lib\site-packages\selenium\webdriver\remote\remote_connection.py", line 316, in _request
    response = self._conn.request(method, url, body=body, headers=headers)
               ^^^^^^^^^^^^^^^^^^^^^^^^^^^^^^^^^^^^^^^^^^^^^^^^^^^^^^^^^^^
  File "C:\Users\pwst\AppData\Local\Programs\Python\Python311\Lib\site-packages\urllib3\request.py", line 74, in request
    return self.request_encode_url(
           ^^^^^^^^^^^^^^^^^^^^^^^^
  File "C:\Users\pwst\AppData\Local\Programs\Python\Python311\Lib\site-packages\urllib3\request.py", line 96, in request_encode_url
    return self.urlopen(method, url, **extra_kw)
           ^^^^^^^^^^^^^^^^^^^^^^^^^^^^^^^^^^^^^
  File "C:\Users\pwst\AppData\Local\Programs\Python\Python311\Lib\site-packages\urllib3\poolmanager.py", line 376, in urlopen
    response = conn.urlopen(method, u.request_uri, **kw)
               ^^^^^^^^^^^^^^^^^^^^^^^^^^^^^^^^^^^^^^^^^
  File "C:\Users\pwst\AppData\Local\Programs\Python\Python311\Lib\site-packages\urllib3\connectionpool.py", line 815, in urlopen
    return self.urlopen(
           ^^^^^^^^^^^^^
  File "C:\Users\pwst\AppData\Local\Programs\Python\Python311\Lib\site-packages\urllib3\connectionpool.py", line 815, in urlopen
    return self.urlopen(
           ^^^^^^^^^^^^^
  File "C:\Users\pwst\AppData\Local\Programs\Python\Python311\Lib\site-packages\urllib3\connectionpool.py", line 815, in urlopen
    return self.urlopen(
           ^^^^^^^^^^^^^
  File "C:\Users\pwst\AppData\Local\Programs\Python\Python311\Lib\site-packages\urllib3\connectionpool.py", line 787, in urlopen
    retries = retries.increment(
              ^^^^^^^^^^^^^^^^^^
  File "C:\Users\pwst\AppData\Local\Programs\Python\Python311\Lib\site-packages\urllib3\util\retry.py", line 592, in increment
    raise MaxRetryError(_pool, url, error or ResponseError(cause))
urllib3.exceptions.MaxRetryError: HTTPConnectionPool(host='localhost', port=53315): Max retries exceeded with url: /session/087d1ef2366c9ea12ffcc182873be34a/screenshot (Caused by NewConnectionError('&lt;urllib3.connection.HTTPConnection object at 0x000001BB6482E010&gt;: Failed to establish a new connection: [WinError 10061] No se puede establecer una conexión ya que el equipo de destino denegó expresamente dicha conexión'))


    </pre>
    </div>
    </td>
    <td align="right">
        <a  href="../../../../img/20221226_12_41_16.png" target="_blank">
            <img src="../../../../img/20221226_12_41_16.png" height="200px" width="400px"/>
        </a>
    </td>
</tr>

<tr id='ft1_4' class='none'>
    <td class='errorCase' width='300px'><div class='testcase'>test_002: Abre la ventana de nuevo y crear un registro</div></td>
    <td colspan='5' align='left' width='600px'> <!--print 输出框位置-->
    <!--默认收起错误信息 -Findyou
    <button id='btn_ft1_4' type="button"  class="btn btn-primary btn-xs collapsed" data-toggle="collapse" data-target='#div_ft1_4'>Error</button>
    <div id='div_ft1_4' class="collapse">  -->
    <!-- 默认展开错误信息 -Findyou -->
    <button id='btn_ft1_4' type="button"  class="btn btn-primary btn-xs" data-toggle="collapse" data-target='#div_ft1_4'>Error</button>
    <div id='div_ft1_4' class="collapse in">
    <pre style="overflow-y:scroll; overflow-x:hidden;height:200px; width:600px; margin:auto; border:1px solid #e1e1e1;">
    
ft1_4: 2022-12-26 12:41:49,265 - root - ERROR - La pantalla ejecutada no es correcta, revise si el xpath sigue siendo el mismo, revise la accion anterior si el xpath es el correcto o el tiempo de la accion
2022-12-26 12:41:49,267 - root - INFO -  Captura: C:\xampp\htdocs\Versiones\automatizaciones\AutoPWST\02FDP\report\img  screen：20221226_12_41_49.png
Traceback (most recent call last):
  File "C:\Users\pwst\AppData\Local\Programs\Python\Python311\Lib\site-packages\urllib3\connection.py", line 174, in _new_conn
    conn = connection.create_connection(
           ^^^^^^^^^^^^^^^^^^^^^^^^^^^^^
  File "C:\Users\pwst\AppData\Local\Programs\Python\Python311\Lib\site-packages\urllib3\util\connection.py", line 95, in create_connection
    raise err
  File "C:\Users\pwst\AppData\Local\Programs\Python\Python311\Lib\site-packages\urllib3\util\connection.py", line 85, in create_connection
    sock.connect(sa)
ConnectionRefusedError: [WinError 10061] No se puede establecer una conexión ya que el equipo de destino denegó expresamente dicha conexión

During handling of the above exception, another exception occurred:

Traceback (most recent call last):
  File "C:\Users\pwst\AppData\Local\Programs\Python\Python311\Lib\site-packages\urllib3\connectionpool.py", line 703, in urlopen
    httplib_response = self._make_request(
                       ^^^^^^^^^^^^^^^^^^^
  File "C:\Users\pwst\AppData\Local\Programs\Python\Python311\Lib\site-packages\urllib3\connectionpool.py", line 398, in _make_request
    conn.request(method, url, **httplib_request_kw)
  File "C:\Users\pwst\AppData\Local\Programs\Python\Python311\Lib\site-packages\urllib3\connection.py", line 239, in request
    super(HTTPConnection, self).request(method, url, body=body, headers=headers)
  File "C:\Users\pwst\AppData\Local\Programs\Python\Python311\Lib\http\client.py", line 1282, in request
    self._send_request(method, url, body, headers, encode_chunked)
  File "C:\Users\pwst\AppData\Local\Programs\Python\Python311\Lib\http\client.py", line 1328, in _send_request
    self.endheaders(body, encode_chunked=encode_chunked)
  File "C:\Users\pwst\AppData\Local\Programs\Python\Python311\Lib\http\client.py", line 1277, in endheaders
    self._send_output(message_body, encode_chunked=encode_chunked)
  File "C:\Users\pwst\AppData\Local\Programs\Python\Python311\Lib\http\client.py", line 1037, in _send_output
    self.send(msg)
  File "C:\Users\pwst\AppData\Local\Programs\Python\Python311\Lib\http\client.py", line 975, in send
    self.connect()
  File "C:\Users\pwst\AppData\Local\Programs\Python\Python311\Lib\site-packages\urllib3\connection.py", line 205, in connect
    conn = self._new_conn()
           ^^^^^^^^^^^^^^^^
  File "C:\Users\pwst\AppData\Local\Programs\Python\Python311\Lib\site-packages\urllib3\connection.py", line 186, in _new_conn
    raise NewConnectionError(
urllib3.exceptions.NewConnectionError: &lt;urllib3.connection.HTTPConnection object at 0x000001BB648655D0&gt;: Failed to establish a new connection: [WinError 10061] No se puede establecer una conexión ya que el equipo de destino denegó expresamente dicha conexión

During handling of the above exception, another exception occurred:

Traceback (most recent call last):
  File "C:\xampp\htdocs\Versiones\automatizaciones\AutoPWST\02FDP\testCase\nuevoregistro.py", line 21, in nuevoregistro
    Crea = self.wait.until(conditions.visibility((By.XPATH, Configuracion.titulo_nuevo))).text
           ^^^^^^^^^^^^^^^^^^^^^^^^^^^^^^^^^^^^^^^^^^^^^^^^^^^^^^^^^^^^^^^^^^^^^^^^^^^^^^
  File "C:\Users\pwst\AppData\Local\Programs\Python\Python311\Lib\site-packages\selenium\webdriver\support\wait.py", line 86, in until
    value = method(self._driver)
            ^^^^^^^^^^^^^^^^^^^^
  File "C:\Users\pwst\AppData\Local\Programs\Python\Python311\Lib\site-packages\selenium\webdriver\support\expected_conditions.py", line 125, in _predicate
    return _element_if_visible(driver.find_element(*locator))
                               ^^^^^^^^^^^^^^^^^^^^^^^^^^^^^
  File "C:\Users\pwst\AppData\Local\Programs\Python\Python311\Lib\site-packages\selenium\webdriver\remote\webdriver.py", line 861, in find_element
    return self.execute(Command.FIND_ELEMENT, {"using": by, "value": value})["value"]
           ^^^^^^^^^^^^^^^^^^^^^^^^^^^^^^^^^^^^^^^^^^^^^^^^^^^^^^^^^^^^^^^^^
  File "C:\Users\pwst\AppData\Local\Programs\Python\Python311\Lib\site-packages\selenium\webdriver\remote\webdriver.py", line 442, in execute
    response = self.command_executor.execute(driver_command, params)
               ^^^^^^^^^^^^^^^^^^^^^^^^^^^^^^^^^^^^^^^^^^^^^^^^^^^^^
  File "C:\Users\pwst\AppData\Local\Programs\Python\Python311\Lib\site-packages\selenium\webdriver\remote\remote_connection.py", line 294, in execute
    return self._request(command_info[0], url, body=data)
           ^^^^^^^^^^^^^^^^^^^^^^^^^^^^^^^^^^^^^^^^^^^^^^
  File "C:\Users\pwst\AppData\Local\Programs\Python\Python311\Lib\site-packages\selenium\webdriver\remote\remote_connection.py", line 316, in _request
    response = self._conn.request(method, url, body=body, headers=headers)
               ^^^^^^^^^^^^^^^^^^^^^^^^^^^^^^^^^^^^^^^^^^^^^^^^^^^^^^^^^^^
  File "C:\Users\pwst\AppData\Local\Programs\Python\Python311\Lib\site-packages\urllib3\request.py", line 78, in request
    return self.request_encode_body(
           ^^^^^^^^^^^^^^^^^^^^^^^^^
  File "C:\Users\pwst\AppData\Local\Programs\Python\Python311\Lib\site-packages\urllib3\request.py", line 170, in request_encode_body
    return self.urlopen(method, url, **extra_kw)
           ^^^^^^^^^^^^^^^^^^^^^^^^^^^^^^^^^^^^^
  File "C:\Users\pwst\AppData\Local\Programs\Python\Python311\Lib\site-packages\urllib3\poolmanager.py", line 376, in urlopen
    response = conn.urlopen(method, u.request_uri, **kw)
               ^^^^^^^^^^^^^^^^^^^^^^^^^^^^^^^^^^^^^^^^^
  File "C:\Users\pwst\AppData\Local\Programs\Python\Python311\Lib\site-packages\urllib3\connectionpool.py", line 815, in urlopen
    return self.urlopen(
           ^^^^^^^^^^^^^
  File "C:\Users\pwst\AppData\Local\Programs\Python\Python311\Lib\site-packages\urllib3\connectionpool.py", line 815, in urlopen
    return self.urlopen(
           ^^^^^^^^^^^^^
  File "C:\Users\pwst\AppData\Local\Programs\Python\Python311\Lib\site-packages\urllib3\connectionpool.py", line 815, in urlopen
    return self.urlopen(
           ^^^^^^^^^^^^^
  File "C:\Users\pwst\AppData\Local\Programs\Python\Python311\Lib\site-packages\urllib3\connectionpool.py", line 787, in urlopen
    retries = retries.increment(
              ^^^^^^^^^^^^^^^^^^
  File "C:\Users\pwst\AppData\Local\Programs\Python\Python311\Lib\site-packages\urllib3\util\retry.py", line 592, in increment
    raise MaxRetryError(_pool, url, error or ResponseError(cause))
urllib3.exceptions.MaxRetryError: HTTPConnectionPool(host='localhost', port=53315): Max retries exceeded with url: /session/087d1ef2366c9ea12ffcc182873be34a/element (Caused by NewConnectionError('&lt;urllib3.connection.HTTPConnection object at 0x000001BB648655D0&gt;: Failed to establish a new connection: [WinError 10061] No se puede establecer una conexión ya que el equipo de destino denegó expresamente dicha conexión'))

During handling of the above exception, another exception occurred:

Traceback (most recent call last):
  File "C:\Users\pwst\AppData\Local\Programs\Python\Python311\Lib\site-packages\urllib3\connection.py", line 174, in _new_conn
    conn = connection.create_connection(
           ^^^^^^^^^^^^^^^^^^^^^^^^^^^^^
  File "C:\Users\pwst\AppData\Local\Programs\Python\Python311\Lib\site-packages\urllib3\util\connection.py", line 95, in create_connection
    raise err
  File "C:\Users\pwst\AppData\Local\Programs\Python\Python311\Lib\site-packages\urllib3\util\connection.py", line 85, in create_connection
    sock.connect(sa)
ConnectionRefusedError: [WinError 10061] No se puede establecer una conexión ya que el equipo de destino denegó expresamente dicha conexión

During handling of the above exception, another exception occurred:

Traceback (most recent call last):
  File "C:\Users\pwst\AppData\Local\Programs\Python\Python311\Lib\site-packages\urllib3\connectionpool.py", line 703, in urlopen
    httplib_response = self._make_request(
                       ^^^^^^^^^^^^^^^^^^^
  File "C:\Users\pwst\AppData\Local\Programs\Python\Python311\Lib\site-packages\urllib3\connectionpool.py", line 398, in _make_request
    conn.request(method, url, **httplib_request_kw)
  File "C:\Users\pwst\AppData\Local\Programs\Python\Python311\Lib\site-packages\urllib3\connection.py", line 239, in request
    super(HTTPConnection, self).request(method, url, body=body, headers=headers)
  File "C:\Users\pwst\AppData\Local\Programs\Python\Python311\Lib\http\client.py", line 1282, in request
    self._send_request(method, url, body, headers, encode_chunked)
  File "C:\Users\pwst\AppData\Local\Programs\Python\Python311\Lib\http\client.py", line 1328, in _send_request
    self.endheaders(body, encode_chunked=encode_chunked)
  File "C:\Users\pwst\AppData\Local\Programs\Python\Python311\Lib\http\client.py", line 1277, in endheaders
    self._send_output(message_body, encode_chunked=encode_chunked)
  File "C:\Users\pwst\AppData\Local\Programs\Python\Python311\Lib\http\client.py", line 1037, in _send_output
    self.send(msg)
  File "C:\Users\pwst\AppData\Local\Programs\Python\Python311\Lib\http\client.py", line 975, in send
    self.connect()
  File "C:\Users\pwst\AppData\Local\Programs\Python\Python311\Lib\site-packages\urllib3\connection.py", line 205, in connect
    conn = self._new_conn()
           ^^^^^^^^^^^^^^^^
  File "C:\Users\pwst\AppData\Local\Programs\Python\Python311\Lib\site-packages\urllib3\connection.py", line 186, in _new_conn
    raise NewConnectionError(
urllib3.exceptions.NewConnectionError: &lt;urllib3.connection.HTTPConnection object at 0x000001BB64867F90&gt;: Failed to establish a new connection: [WinError 10061] No se puede establecer una conexión ya que el equipo de destino denegó expresamente dicha conexión

During handling of the above exception, another exception occurred:

Traceback (most recent call last):
  File "C:\xampp\htdocs\Versiones\automatizaciones\AutoPWST\02FDP\testCase\formasdepago.py", line 58, in test_002
    success = nuevoregistro.nuevoregistro.nuevoregistro(self, conditions, Configuracion)
              ^^^^^^^^^^^^^^^^^^^^^^^^^^^^^^^^^^^^^^^^^^^^^^^^^^^^^^^^^^^^^^^^^^^^^^^^^^
  File "C:\xampp\htdocs\Versiones\automatizaciones\AutoPWST\02FDP\testCase\nuevoregistro.py", line 31, in nuevoregistro
    self.driver.get_screenshot_as_file(img_name)
  File "C:\Users\pwst\AppData\Local\Programs\Python\Python311\Lib\site-packages\selenium\webdriver\remote\webdriver.py", line 929, in get_screenshot_as_file
    png = self.get_screenshot_as_png()
          ^^^^^^^^^^^^^^^^^^^^^^^^^^^^
  File "C:\Users\pwst\AppData\Local\Programs\Python\Python311\Lib\site-packages\selenium\webdriver\remote\webdriver.py", line 965, in get_screenshot_as_png
    return b64decode(self.get_screenshot_as_base64().encode("ascii"))
                     ^^^^^^^^^^^^^^^^^^^^^^^^^^^^^^^
  File "C:\Users\pwst\AppData\Local\Programs\Python\Python311\Lib\site-packages\selenium\webdriver\remote\webdriver.py", line 977, in get_screenshot_as_base64
    return self.execute(Command.SCREENSHOT)["value"]
           ^^^^^^^^^^^^^^^^^^^^^^^^^^^^^^^^
  File "C:\Users\pwst\AppData\Local\Programs\Python\Python311\Lib\site-packages\selenium\webdriver\remote\webdriver.py", line 442, in execute
    response = self.command_executor.execute(driver_command, params)
               ^^^^^^^^^^^^^^^^^^^^^^^^^^^^^^^^^^^^^^^^^^^^^^^^^^^^^
  File "C:\Users\pwst\AppData\Local\Programs\Python\Python311\Lib\site-packages\selenium\webdriver\remote\remote_connection.py", line 294, in execute
    return self._request(command_info[0], url, body=data)
           ^^^^^^^^^^^^^^^^^^^^^^^^^^^^^^^^^^^^^^^^^^^^^^
  File "C:\Users\pwst\AppData\Local\Programs\Python\Python311\Lib\site-packages\selenium\webdriver\remote\remote_connection.py", line 316, in _request
    response = self._conn.request(method, url, body=body, headers=headers)
               ^^^^^^^^^^^^^^^^^^^^^^^^^^^^^^^^^^^^^^^^^^^^^^^^^^^^^^^^^^^
  File "C:\Users\pwst\AppData\Local\Programs\Python\Python311\Lib\site-packages\urllib3\request.py", line 74, in request
    return self.request_encode_url(
           ^^^^^^^^^^^^^^^^^^^^^^^^
  File "C:\Users\pwst\AppData\Local\Programs\Python\Python311\Lib\site-packages\urllib3\request.py", line 96, in request_encode_url
    return self.urlopen(method, url, **extra_kw)
           ^^^^^^^^^^^^^^^^^^^^^^^^^^^^^^^^^^^^^
  File "C:\Users\pwst\AppData\Local\Programs\Python\Python311\Lib\site-packages\urllib3\poolmanager.py", line 376, in urlopen
    response = conn.urlopen(method, u.request_uri, **kw)
               ^^^^^^^^^^^^^^^^^^^^^^^^^^^^^^^^^^^^^^^^^
  File "C:\Users\pwst\AppData\Local\Programs\Python\Python311\Lib\site-packages\urllib3\connectionpool.py", line 815, in urlopen
    return self.urlopen(
           ^^^^^^^^^^^^^
  File "C:\Users\pwst\AppData\Local\Programs\Python\Python311\Lib\site-packages\urllib3\connectionpool.py", line 815, in urlopen
    return self.urlopen(
           ^^^^^^^^^^^^^
  File "C:\Users\pwst\AppData\Local\Programs\Python\Python311\Lib\site-packages\urllib3\connectionpool.py", line 815, in urlopen
    return self.urlopen(
           ^^^^^^^^^^^^^
  File "C:\Users\pwst\AppData\Local\Programs\Python\Python311\Lib\site-packages\urllib3\connectionpool.py", line 787, in urlopen
    retries = retries.increment(
              ^^^^^^^^^^^^^^^^^^
  File "C:\Users\pwst\AppData\Local\Programs\Python\Python311\Lib\site-packages\urllib3\util\retry.py", line 592, in increment
    raise MaxRetryError(_pool, url, error or ResponseError(cause))
urllib3.exceptions.MaxRetryError: HTTPConnectionPool(host='localhost', port=53315): Max retries exceeded with url: /session/087d1ef2366c9ea12ffcc182873be34a/screenshot (Caused by NewConnectionError('&lt;urllib3.connection.HTTPConnection object at 0x000001BB64867F90&gt;: Failed to establish a new connection: [WinError 10061] No se puede establecer una conexión ya que el equipo de destino denegó expresamente dicha conexión'))


    </pre>
    </div>
    </td>
    <td align="right">
        <a  href="../../../../img/20221226_12_41_49.png" target="_blank">
            <img src="../../../../img/20221226_12_41_49.png" height="200px" width="400px"/>
        </a>
    </td>
</tr>

<tr id='ft1_5' class='none'>
    <td class='errorCase' width='300px'><div class='testcase'>test_003: Repetir el registro creado anteriormente</div></td>
    <td colspan='5' align='left' width='600px'> <!--print 输出框位置-->
    <!--默认收起错误信息 -Findyou
    <button id='btn_ft1_5' type="button"  class="btn btn-primary btn-xs collapsed" data-toggle="collapse" data-target='#div_ft1_5'>Error</button>
    <div id='div_ft1_5' class="collapse">  -->
    <!-- 默认展开错误信息 -Findyou -->
    <button id='btn_ft1_5' type="button"  class="btn btn-primary btn-xs" data-toggle="collapse" data-target='#div_ft1_5'>Error</button>
    <div id='div_ft1_5' class="collapse in">
    <pre style="overflow-y:scroll; overflow-x:hidden;height:200px; width:600px; margin:auto; border:1px solid #e1e1e1;">
    
ft1_5: 2022-12-26 12:42:21,990 - root - ERROR - No se dió click al botón Refrescar, revise si el xpath sigue siendo el mismo, revise la accion anterior si el xpath es el correcto o el tiempo de la accion o si ya existe el registro ya crado igual
2022-12-26 12:42:21,992 - root - INFO -  Captura: C:\xampp\htdocs\Versiones\automatizaciones\AutoPWST\02FDP\report\img  screen：20221226_12_42_21.png
Traceback (most recent call last):
  File "C:\Users\pwst\AppData\Local\Programs\Python\Python311\Lib\site-packages\urllib3\connection.py", line 174, in _new_conn
    conn = connection.create_connection(
           ^^^^^^^^^^^^^^^^^^^^^^^^^^^^^
  File "C:\Users\pwst\AppData\Local\Programs\Python\Python311\Lib\site-packages\urllib3\util\connection.py", line 95, in create_connection
    raise err
  File "C:\Users\pwst\AppData\Local\Programs\Python\Python311\Lib\site-packages\urllib3\util\connection.py", line 85, in create_connection
    sock.connect(sa)
ConnectionRefusedError: [WinError 10061] No se puede establecer una conexión ya que el equipo de destino denegó expresamente dicha conexión

During handling of the above exception, another exception occurred:

Traceback (most recent call last):
  File "C:\Users\pwst\AppData\Local\Programs\Python\Python311\Lib\site-packages\urllib3\connectionpool.py", line 703, in urlopen
    httplib_response = self._make_request(
                       ^^^^^^^^^^^^^^^^^^^
  File "C:\Users\pwst\AppData\Local\Programs\Python\Python311\Lib\site-packages\urllib3\connectionpool.py", line 398, in _make_request
    conn.request(method, url, **httplib_request_kw)
  File "C:\Users\pwst\AppData\Local\Programs\Python\Python311\Lib\site-packages\urllib3\connection.py", line 239, in request
    super(HTTPConnection, self).request(method, url, body=body, headers=headers)
  File "C:\Users\pwst\AppData\Local\Programs\Python\Python311\Lib\http\client.py", line 1282, in request
    self._send_request(method, url, body, headers, encode_chunked)
  File "C:\Users\pwst\AppData\Local\Programs\Python\Python311\Lib\http\client.py", line 1328, in _send_request
    self.endheaders(body, encode_chunked=encode_chunked)
  File "C:\Users\pwst\AppData\Local\Programs\Python\Python311\Lib\http\client.py", line 1277, in endheaders
    self._send_output(message_body, encode_chunked=encode_chunked)
  File "C:\Users\pwst\AppData\Local\Programs\Python\Python311\Lib\http\client.py", line 1037, in _send_output
    self.send(msg)
  File "C:\Users\pwst\AppData\Local\Programs\Python\Python311\Lib\http\client.py", line 975, in send
    self.connect()
  File "C:\Users\pwst\AppData\Local\Programs\Python\Python311\Lib\site-packages\urllib3\connection.py", line 205, in connect
    conn = self._new_conn()
           ^^^^^^^^^^^^^^^^
  File "C:\Users\pwst\AppData\Local\Programs\Python\Python311\Lib\site-packages\urllib3\connection.py", line 186, in _new_conn
    raise NewConnectionError(
urllib3.exceptions.NewConnectionError: &lt;urllib3.connection.HTTPConnection object at 0x000001BB64449490&gt;: Failed to establish a new connection: [WinError 10061] No se puede establecer una conexión ya que el equipo de destino denegó expresamente dicha conexión

During handling of the above exception, another exception occurred:

Traceback (most recent call last):
  File "C:\xampp\htdocs\Versiones\automatizaciones\AutoPWST\02FDP\testCase\repetirregistro.py", line 22, in repetirregistro
    Refresca = self.wait.until(conditions.visibility((By.XPATH, Configuracion.btn_Refresca)))
               ^^^^^^^^^^^^^^^^^^^^^^^^^^^^^^^^^^^^^^^^^^^^^^^^^^^^^^^^^^^^^^^^^^^^^^^^^^^^^^
  File "C:\Users\pwst\AppData\Local\Programs\Python\Python311\Lib\site-packages\selenium\webdriver\support\wait.py", line 86, in until
    value = method(self._driver)
            ^^^^^^^^^^^^^^^^^^^^
  File "C:\Users\pwst\AppData\Local\Programs\Python\Python311\Lib\site-packages\selenium\webdriver\support\expected_conditions.py", line 125, in _predicate
    return _element_if_visible(driver.find_element(*locator))
                               ^^^^^^^^^^^^^^^^^^^^^^^^^^^^^
  File "C:\Users\pwst\AppData\Local\Programs\Python\Python311\Lib\site-packages\selenium\webdriver\remote\webdriver.py", line 861, in find_element
    return self.execute(Command.FIND_ELEMENT, {"using": by, "value": value})["value"]
           ^^^^^^^^^^^^^^^^^^^^^^^^^^^^^^^^^^^^^^^^^^^^^^^^^^^^^^^^^^^^^^^^^
  File "C:\Users\pwst\AppData\Local\Programs\Python\Python311\Lib\site-packages\selenium\webdriver\remote\webdriver.py", line 442, in execute
    response = self.command_executor.execute(driver_command, params)
               ^^^^^^^^^^^^^^^^^^^^^^^^^^^^^^^^^^^^^^^^^^^^^^^^^^^^^
  File "C:\Users\pwst\AppData\Local\Programs\Python\Python311\Lib\site-packages\selenium\webdriver\remote\remote_connection.py", line 294, in execute
    return self._request(command_info[0], url, body=data)
           ^^^^^^^^^^^^^^^^^^^^^^^^^^^^^^^^^^^^^^^^^^^^^^
  File "C:\Users\pwst\AppData\Local\Programs\Python\Python311\Lib\site-packages\selenium\webdriver\remote\remote_connection.py", line 316, in _request
    response = self._conn.request(method, url, body=body, headers=headers)
               ^^^^^^^^^^^^^^^^^^^^^^^^^^^^^^^^^^^^^^^^^^^^^^^^^^^^^^^^^^^
  File "C:\Users\pwst\AppData\Local\Programs\Python\Python311\Lib\site-packages\urllib3\request.py", line 78, in request
    return self.request_encode_body(
           ^^^^^^^^^^^^^^^^^^^^^^^^^
  File "C:\Users\pwst\AppData\Local\Programs\Python\Python311\Lib\site-packages\urllib3\request.py", line 170, in request_encode_body
    return self.urlopen(method, url, **extra_kw)
           ^^^^^^^^^^^^^^^^^^^^^^^^^^^^^^^^^^^^^
  File "C:\Users\pwst\AppData\Local\Programs\Python\Python311\Lib\site-packages\urllib3\poolmanager.py", line 376, in urlopen
    response = conn.urlopen(method, u.request_uri, **kw)
               ^^^^^^^^^^^^^^^^^^^^^^^^^^^^^^^^^^^^^^^^^
  File "C:\Users\pwst\AppData\Local\Programs\Python\Python311\Lib\site-packages\urllib3\connectionpool.py", line 815, in urlopen
    return self.urlopen(
           ^^^^^^^^^^^^^
  File "C:\Users\pwst\AppData\Local\Programs\Python\Python311\Lib\site-packages\urllib3\connectionpool.py", line 815, in urlopen
    return self.urlopen(
           ^^^^^^^^^^^^^
  File "C:\Users\pwst\AppData\Local\Programs\Python\Python311\Lib\site-packages\urllib3\connectionpool.py", line 815, in urlopen
    return self.urlopen(
           ^^^^^^^^^^^^^
  File "C:\Users\pwst\AppData\Local\Programs\Python\Python311\Lib\site-packages\urllib3\connectionpool.py", line 787, in urlopen
    retries = retries.increment(
              ^^^^^^^^^^^^^^^^^^
  File "C:\Users\pwst\AppData\Local\Programs\Python\Python311\Lib\site-packages\urllib3\util\retry.py", line 592, in increment
    raise MaxRetryError(_pool, url, error or ResponseError(cause))
urllib3.exceptions.MaxRetryError: HTTPConnectionPool(host='localhost', port=53315): Max retries exceeded with url: /session/087d1ef2366c9ea12ffcc182873be34a/element (Caused by NewConnectionError('&lt;urllib3.connection.HTTPConnection object at 0x000001BB64449490&gt;: Failed to establish a new connection: [WinError 10061] No se puede establecer una conexión ya que el equipo de destino denegó expresamente dicha conexión'))

During handling of the above exception, another exception occurred:

Traceback (most recent call last):
  File "C:\Users\pwst\AppData\Local\Programs\Python\Python311\Lib\site-packages\urllib3\connection.py", line 174, in _new_conn
    conn = connection.create_connection(
           ^^^^^^^^^^^^^^^^^^^^^^^^^^^^^
  File "C:\Users\pwst\AppData\Local\Programs\Python\Python311\Lib\site-packages\urllib3\util\connection.py", line 95, in create_connection
    raise err
  File "C:\Users\pwst\AppData\Local\Programs\Python\Python311\Lib\site-packages\urllib3\util\connection.py", line 85, in create_connection
    sock.connect(sa)
ConnectionRefusedError: [WinError 10061] No se puede establecer una conexión ya que el equipo de destino denegó expresamente dicha conexión

During handling of the above exception, another exception occurred:

Traceback (most recent call last):
  File "C:\Users\pwst\AppData\Local\Programs\Python\Python311\Lib\site-packages\urllib3\connectionpool.py", line 703, in urlopen
    httplib_response = self._make_request(
                       ^^^^^^^^^^^^^^^^^^^
  File "C:\Users\pwst\AppData\Local\Programs\Python\Python311\Lib\site-packages\urllib3\connectionpool.py", line 398, in _make_request
    conn.request(method, url, **httplib_request_kw)
  File "C:\Users\pwst\AppData\Local\Programs\Python\Python311\Lib\site-packages\urllib3\connection.py", line 239, in request
    super(HTTPConnection, self).request(method, url, body=body, headers=headers)
  File "C:\Users\pwst\AppData\Local\Programs\Python\Python311\Lib\http\client.py", line 1282, in request
    self._send_request(method, url, body, headers, encode_chunked)
  File "C:\Users\pwst\AppData\Local\Programs\Python\Python311\Lib\http\client.py", line 1328, in _send_request
    self.endheaders(body, encode_chunked=encode_chunked)
  File "C:\Users\pwst\AppData\Local\Programs\Python\Python311\Lib\http\client.py", line 1277, in endheaders
    self._send_output(message_body, encode_chunked=encode_chunked)
  File "C:\Users\pwst\AppData\Local\Programs\Python\Python311\Lib\http\client.py", line 1037, in _send_output
    self.send(msg)
  File "C:\Users\pwst\AppData\Local\Programs\Python\Python311\Lib\http\client.py", line 975, in send
    self.connect()
  File "C:\Users\pwst\AppData\Local\Programs\Python\Python311\Lib\site-packages\urllib3\connection.py", line 205, in connect
    conn = self._new_conn()
           ^^^^^^^^^^^^^^^^
  File "C:\Users\pwst\AppData\Local\Programs\Python\Python311\Lib\site-packages\urllib3\connection.py", line 186, in _new_conn
    raise NewConnectionError(
urllib3.exceptions.NewConnectionError: &lt;urllib3.connection.HTTPConnection object at 0x000001BB64866910&gt;: Failed to establish a new connection: [WinError 10061] No se puede establecer una conexión ya que el equipo de destino denegó expresamente dicha conexión

During handling of the above exception, another exception occurred:

Traceback (most recent call last):
  File "C:\xampp\htdocs\Versiones\automatizaciones\AutoPWST\02FDP\testCase\formasdepago.py", line 74, in test_003
    success = repetirregistro.repetirregistro.repetirregistro(self, conditions, Configuracion)
              ^^^^^^^^^^^^^^^^^^^^^^^^^^^^^^^^^^^^^^^^^^^^^^^^^^^^^^^^^^^^^^^^^^^^^^^^^^^^^^^^
  File "C:\xampp\htdocs\Versiones\automatizaciones\AutoPWST\02FDP\testCase\repetirregistro.py", line 33, in repetirregistro
    self.driver.get_screenshot_as_file(img_name)
  File "C:\Users\pwst\AppData\Local\Programs\Python\Python311\Lib\site-packages\selenium\webdriver\remote\webdriver.py", line 929, in get_screenshot_as_file
    png = self.get_screenshot_as_png()
          ^^^^^^^^^^^^^^^^^^^^^^^^^^^^
  File "C:\Users\pwst\AppData\Local\Programs\Python\Python311\Lib\site-packages\selenium\webdriver\remote\webdriver.py", line 965, in get_screenshot_as_png
    return b64decode(self.get_screenshot_as_base64().encode("ascii"))
                     ^^^^^^^^^^^^^^^^^^^^^^^^^^^^^^^
  File "C:\Users\pwst\AppData\Local\Programs\Python\Python311\Lib\site-packages\selenium\webdriver\remote\webdriver.py", line 977, in get_screenshot_as_base64
    return self.execute(Command.SCREENSHOT)["value"]
           ^^^^^^^^^^^^^^^^^^^^^^^^^^^^^^^^
  File "C:\Users\pwst\AppData\Local\Programs\Python\Python311\Lib\site-packages\selenium\webdriver\remote\webdriver.py", line 442, in execute
    response = self.command_executor.execute(driver_command, params)
               ^^^^^^^^^^^^^^^^^^^^^^^^^^^^^^^^^^^^^^^^^^^^^^^^^^^^^
  File "C:\Users\pwst\AppData\Local\Programs\Python\Python311\Lib\site-packages\selenium\webdriver\remote\remote_connection.py", line 294, in execute
    return self._request(command_info[0], url, body=data)
           ^^^^^^^^^^^^^^^^^^^^^^^^^^^^^^^^^^^^^^^^^^^^^^
  File "C:\Users\pwst\AppData\Local\Programs\Python\Python311\Lib\site-packages\selenium\webdriver\remote\remote_connection.py", line 316, in _request
    response = self._conn.request(method, url, body=body, headers=headers)
               ^^^^^^^^^^^^^^^^^^^^^^^^^^^^^^^^^^^^^^^^^^^^^^^^^^^^^^^^^^^
  File "C:\Users\pwst\AppData\Local\Programs\Python\Python311\Lib\site-packages\urllib3\request.py", line 74, in request
    return self.request_encode_url(
           ^^^^^^^^^^^^^^^^^^^^^^^^
  File "C:\Users\pwst\AppData\Local\Programs\Python\Python311\Lib\site-packages\urllib3\request.py", line 96, in request_encode_url
    return self.urlopen(method, url, **extra_kw)
           ^^^^^^^^^^^^^^^^^^^^^^^^^^^^^^^^^^^^^
  File "C:\Users\pwst\AppData\Local\Programs\Python\Python311\Lib\site-packages\urllib3\poolmanager.py", line 376, in urlopen
    response = conn.urlopen(method, u.request_uri, **kw)
               ^^^^^^^^^^^^^^^^^^^^^^^^^^^^^^^^^^^^^^^^^
  File "C:\Users\pwst\AppData\Local\Programs\Python\Python311\Lib\site-packages\urllib3\connectionpool.py", line 815, in urlopen
    return self.urlopen(
           ^^^^^^^^^^^^^
  File "C:\Users\pwst\AppData\Local\Programs\Python\Python311\Lib\site-packages\urllib3\connectionpool.py", line 815, in urlopen
    return self.urlopen(
           ^^^^^^^^^^^^^
  File "C:\Users\pwst\AppData\Local\Programs\Python\Python311\Lib\site-packages\urllib3\connectionpool.py", line 815, in urlopen
    return self.urlopen(
           ^^^^^^^^^^^^^
  File "C:\Users\pwst\AppData\Local\Programs\Python\Python311\Lib\site-packages\urllib3\connectionpool.py", line 787, in urlopen
    retries = retries.increment(
              ^^^^^^^^^^^^^^^^^^
  File "C:\Users\pwst\AppData\Local\Programs\Python\Python311\Lib\site-packages\urllib3\util\retry.py", line 592, in increment
    raise MaxRetryError(_pool, url, error or ResponseError(cause))
urllib3.exceptions.MaxRetryError: HTTPConnectionPool(host='localhost', port=53315): Max retries exceeded with url: /session/087d1ef2366c9ea12ffcc182873be34a/screenshot (Caused by NewConnectionError('&lt;urllib3.connection.HTTPConnection object at 0x000001BB64866910&gt;: Failed to establish a new connection: [WinError 10061] No se puede establecer una conexión ya que el equipo de destino denegó expresamente dicha conexión'))


    </pre>
    </div>
    </td>
    <td align="right">
        <a  href="../../../../img/20221226_12_42_21.png" target="_blank">
            <img src="../../../../img/20221226_12_42_21.png" height="200px" width="400px"/>
        </a>
    </td>
</tr>

<tr id='ft1_6' class='none'>
    <td class='errorCase' width='300px'><div class='testcase'>test_004: Modificar el registro</div></td>
    <td colspan='5' align='left' width='600px'> <!--print 输出框位置-->
    <!--默认收起错误信息 -Findyou
    <button id='btn_ft1_6' type="button"  class="btn btn-primary btn-xs collapsed" data-toggle="collapse" data-target='#div_ft1_6'>Error</button>
    <div id='div_ft1_6' class="collapse">  -->
    <!-- 默认展开错误信息 -Findyou -->
    <button id='btn_ft1_6' type="button"  class="btn btn-primary btn-xs" data-toggle="collapse" data-target='#div_ft1_6'>Error</button>
    <div id='div_ft1_6' class="collapse in">
    <pre style="overflow-y:scroll; overflow-x:hidden;height:200px; width:600px; margin:auto; border:1px solid #e1e1e1;">
    
ft1_6: 2022-12-26 12:42:54,782 - root - ERROR - No se dió click al botón Refrescar, revise si el xpath sigue siendo el mismo, revise la accion anterior si el xpath es el correcto o el tiempo de la accion
2022-12-26 12:42:54,783 - root - INFO -  Captura: C:\xampp\htdocs\Versiones\automatizaciones\AutoPWST\02FDP\report\img  screen：20221226_12_42_54.png
Traceback (most recent call last):
  File "C:\Users\pwst\AppData\Local\Programs\Python\Python311\Lib\site-packages\urllib3\connection.py", line 174, in _new_conn
    conn = connection.create_connection(
           ^^^^^^^^^^^^^^^^^^^^^^^^^^^^^
  File "C:\Users\pwst\AppData\Local\Programs\Python\Python311\Lib\site-packages\urllib3\util\connection.py", line 95, in create_connection
    raise err
  File "C:\Users\pwst\AppData\Local\Programs\Python\Python311\Lib\site-packages\urllib3\util\connection.py", line 85, in create_connection
    sock.connect(sa)
ConnectionRefusedError: [WinError 10061] No se puede establecer una conexión ya que el equipo de destino denegó expresamente dicha conexión

During handling of the above exception, another exception occurred:

Traceback (most recent call last):
  File "C:\Users\pwst\AppData\Local\Programs\Python\Python311\Lib\site-packages\urllib3\connectionpool.py", line 703, in urlopen
    httplib_response = self._make_request(
                       ^^^^^^^^^^^^^^^^^^^
  File "C:\Users\pwst\AppData\Local\Programs\Python\Python311\Lib\site-packages\urllib3\connectionpool.py", line 398, in _make_request
    conn.request(method, url, **httplib_request_kw)
  File "C:\Users\pwst\AppData\Local\Programs\Python\Python311\Lib\site-packages\urllib3\connection.py", line 239, in request
    super(HTTPConnection, self).request(method, url, body=body, headers=headers)
  File "C:\Users\pwst\AppData\Local\Programs\Python\Python311\Lib\http\client.py", line 1282, in request
    self._send_request(method, url, body, headers, encode_chunked)
  File "C:\Users\pwst\AppData\Local\Programs\Python\Python311\Lib\http\client.py", line 1328, in _send_request
    self.endheaders(body, encode_chunked=encode_chunked)
  File "C:\Users\pwst\AppData\Local\Programs\Python\Python311\Lib\http\client.py", line 1277, in endheaders
    self._send_output(message_body, encode_chunked=encode_chunked)
  File "C:\Users\pwst\AppData\Local\Programs\Python\Python311\Lib\http\client.py", line 1037, in _send_output
    self.send(msg)
  File "C:\Users\pwst\AppData\Local\Programs\Python\Python311\Lib\http\client.py", line 975, in send
    self.connect()
  File "C:\Users\pwst\AppData\Local\Programs\Python\Python311\Lib\site-packages\urllib3\connection.py", line 205, in connect
    conn = self._new_conn()
           ^^^^^^^^^^^^^^^^
  File "C:\Users\pwst\AppData\Local\Programs\Python\Python311\Lib\site-packages\urllib3\connection.py", line 186, in _new_conn
    raise NewConnectionError(
urllib3.exceptions.NewConnectionError: &lt;urllib3.connection.HTTPConnection object at 0x000001BB6482F050&gt;: Failed to establish a new connection: [WinError 10061] No se puede establecer una conexión ya que el equipo de destino denegó expresamente dicha conexión

During handling of the above exception, another exception occurred:

Traceback (most recent call last):
  File "C:\xampp\htdocs\Versiones\automatizaciones\AutoPWST\02FDP\testCase\modificarregistro.py", line 22, in modificarregistro
    Refresca2 = self.wait.until(conditions.visibility((By.XPATH, Configuracion.btn_Refresca)))
                ^^^^^^^^^^^^^^^^^^^^^^^^^^^^^^^^^^^^^^^^^^^^^^^^^^^^^^^^^^^^^^^^^^^^^^^^^^^^^^
  File "C:\Users\pwst\AppData\Local\Programs\Python\Python311\Lib\site-packages\selenium\webdriver\support\wait.py", line 86, in until
    value = method(self._driver)
            ^^^^^^^^^^^^^^^^^^^^
  File "C:\Users\pwst\AppData\Local\Programs\Python\Python311\Lib\site-packages\selenium\webdriver\support\expected_conditions.py", line 125, in _predicate
    return _element_if_visible(driver.find_element(*locator))
                               ^^^^^^^^^^^^^^^^^^^^^^^^^^^^^
  File "C:\Users\pwst\AppData\Local\Programs\Python\Python311\Lib\site-packages\selenium\webdriver\remote\webdriver.py", line 861, in find_element
    return self.execute(Command.FIND_ELEMENT, {"using": by, "value": value})["value"]
           ^^^^^^^^^^^^^^^^^^^^^^^^^^^^^^^^^^^^^^^^^^^^^^^^^^^^^^^^^^^^^^^^^
  File "C:\Users\pwst\AppData\Local\Programs\Python\Python311\Lib\site-packages\selenium\webdriver\remote\webdriver.py", line 442, in execute
    response = self.command_executor.execute(driver_command, params)
               ^^^^^^^^^^^^^^^^^^^^^^^^^^^^^^^^^^^^^^^^^^^^^^^^^^^^^
  File "C:\Users\pwst\AppData\Local\Programs\Python\Python311\Lib\site-packages\selenium\webdriver\remote\remote_connection.py", line 294, in execute
    return self._request(command_info[0], url, body=data)
           ^^^^^^^^^^^^^^^^^^^^^^^^^^^^^^^^^^^^^^^^^^^^^^
  File "C:\Users\pwst\AppData\Local\Programs\Python\Python311\Lib\site-packages\selenium\webdriver\remote\remote_connection.py", line 316, in _request
    response = self._conn.request(method, url, body=body, headers=headers)
               ^^^^^^^^^^^^^^^^^^^^^^^^^^^^^^^^^^^^^^^^^^^^^^^^^^^^^^^^^^^
  File "C:\Users\pwst\AppData\Local\Programs\Python\Python311\Lib\site-packages\urllib3\request.py", line 78, in request
    return self.request_encode_body(
           ^^^^^^^^^^^^^^^^^^^^^^^^^
  File "C:\Users\pwst\AppData\Local\Programs\Python\Python311\Lib\site-packages\urllib3\request.py", line 170, in request_encode_body
    return self.urlopen(method, url, **extra_kw)
           ^^^^^^^^^^^^^^^^^^^^^^^^^^^^^^^^^^^^^
  File "C:\Users\pwst\AppData\Local\Programs\Python\Python311\Lib\site-packages\urllib3\poolmanager.py", line 376, in urlopen
    response = conn.urlopen(method, u.request_uri, **kw)
               ^^^^^^^^^^^^^^^^^^^^^^^^^^^^^^^^^^^^^^^^^
  File "C:\Users\pwst\AppData\Local\Programs\Python\Python311\Lib\site-packages\urllib3\connectionpool.py", line 815, in urlopen
    return self.urlopen(
           ^^^^^^^^^^^^^
  File "C:\Users\pwst\AppData\Local\Programs\Python\Python311\Lib\site-packages\urllib3\connectionpool.py", line 815, in urlopen
    return self.urlopen(
           ^^^^^^^^^^^^^
  File "C:\Users\pwst\AppData\Local\Programs\Python\Python311\Lib\site-packages\urllib3\connectionpool.py", line 815, in urlopen
    return self.urlopen(
           ^^^^^^^^^^^^^
  File "C:\Users\pwst\AppData\Local\Programs\Python\Python311\Lib\site-packages\urllib3\connectionpool.py", line 787, in urlopen
    retries = retries.increment(
              ^^^^^^^^^^^^^^^^^^
  File "C:\Users\pwst\AppData\Local\Programs\Python\Python311\Lib\site-packages\urllib3\util\retry.py", line 592, in increment
    raise MaxRetryError(_pool, url, error or ResponseError(cause))
urllib3.exceptions.MaxRetryError: HTTPConnectionPool(host='localhost', port=53315): Max retries exceeded with url: /session/087d1ef2366c9ea12ffcc182873be34a/element (Caused by NewConnectionError('&lt;urllib3.connection.HTTPConnection object at 0x000001BB6482F050&gt;: Failed to establish a new connection: [WinError 10061] No se puede establecer una conexión ya que el equipo de destino denegó expresamente dicha conexión'))

During handling of the above exception, another exception occurred:

Traceback (most recent call last):
  File "C:\Users\pwst\AppData\Local\Programs\Python\Python311\Lib\site-packages\urllib3\connection.py", line 174, in _new_conn
    conn = connection.create_connection(
           ^^^^^^^^^^^^^^^^^^^^^^^^^^^^^
  File "C:\Users\pwst\AppData\Local\Programs\Python\Python311\Lib\site-packages\urllib3\util\connection.py", line 95, in create_connection
    raise err
  File "C:\Users\pwst\AppData\Local\Programs\Python\Python311\Lib\site-packages\urllib3\util\connection.py", line 85, in create_connection
    sock.connect(sa)
ConnectionRefusedError: [WinError 10061] No se puede establecer una conexión ya que el equipo de destino denegó expresamente dicha conexión

During handling of the above exception, another exception occurred:

Traceback (most recent call last):
  File "C:\Users\pwst\AppData\Local\Programs\Python\Python311\Lib\site-packages\urllib3\connectionpool.py", line 703, in urlopen
    httplib_response = self._make_request(
                       ^^^^^^^^^^^^^^^^^^^
  File "C:\Users\pwst\AppData\Local\Programs\Python\Python311\Lib\site-packages\urllib3\connectionpool.py", line 398, in _make_request
    conn.request(method, url, **httplib_request_kw)
  File "C:\Users\pwst\AppData\Local\Programs\Python\Python311\Lib\site-packages\urllib3\connection.py", line 239, in request
    super(HTTPConnection, self).request(method, url, body=body, headers=headers)
  File "C:\Users\pwst\AppData\Local\Programs\Python\Python311\Lib\http\client.py", line 1282, in request
    self._send_request(method, url, body, headers, encode_chunked)
  File "C:\Users\pwst\AppData\Local\Programs\Python\Python311\Lib\http\client.py", line 1328, in _send_request
    self.endheaders(body, encode_chunked=encode_chunked)
  File "C:\Users\pwst\AppData\Local\Programs\Python\Python311\Lib\http\client.py", line 1277, in endheaders
    self._send_output(message_body, encode_chunked=encode_chunked)
  File "C:\Users\pwst\AppData\Local\Programs\Python\Python311\Lib\http\client.py", line 1037, in _send_output
    self.send(msg)
  File "C:\Users\pwst\AppData\Local\Programs\Python\Python311\Lib\http\client.py", line 975, in send
    self.connect()
  File "C:\Users\pwst\AppData\Local\Programs\Python\Python311\Lib\site-packages\urllib3\connection.py", line 205, in connect
    conn = self._new_conn()
           ^^^^^^^^^^^^^^^^
  File "C:\Users\pwst\AppData\Local\Programs\Python\Python311\Lib\site-packages\urllib3\connection.py", line 186, in _new_conn
    raise NewConnectionError(
urllib3.exceptions.NewConnectionError: &lt;urllib3.connection.HTTPConnection object at 0x000001BB6489CC90&gt;: Failed to establish a new connection: [WinError 10061] No se puede establecer una conexión ya que el equipo de destino denegó expresamente dicha conexión

During handling of the above exception, another exception occurred:

Traceback (most recent call last):
  File "C:\xampp\htdocs\Versiones\automatizaciones\AutoPWST\02FDP\testCase\formasdepago.py", line 102, in test_004
    success = modificarregistro.modificarregistro.modificarregistro(self, conditions, Configuracion)
              ^^^^^^^^^^^^^^^^^^^^^^^^^^^^^^^^^^^^^^^^^^^^^^^^^^^^^^^^^^^^^^^^^^^^^^^^^^^^^^^^^^^^^^
  File "C:\xampp\htdocs\Versiones\automatizaciones\AutoPWST\02FDP\testCase\modificarregistro.py", line 33, in modificarregistro
    self.driver.get_screenshot_as_file(img_name)
  File "C:\Users\pwst\AppData\Local\Programs\Python\Python311\Lib\site-packages\selenium\webdriver\remote\webdriver.py", line 929, in get_screenshot_as_file
    png = self.get_screenshot_as_png()
          ^^^^^^^^^^^^^^^^^^^^^^^^^^^^
  File "C:\Users\pwst\AppData\Local\Programs\Python\Python311\Lib\site-packages\selenium\webdriver\remote\webdriver.py", line 965, in get_screenshot_as_png
    return b64decode(self.get_screenshot_as_base64().encode("ascii"))
                     ^^^^^^^^^^^^^^^^^^^^^^^^^^^^^^^
  File "C:\Users\pwst\AppData\Local\Programs\Python\Python311\Lib\site-packages\selenium\webdriver\remote\webdriver.py", line 977, in get_screenshot_as_base64
    return self.execute(Command.SCREENSHOT)["value"]
           ^^^^^^^^^^^^^^^^^^^^^^^^^^^^^^^^
  File "C:\Users\pwst\AppData\Local\Programs\Python\Python311\Lib\site-packages\selenium\webdriver\remote\webdriver.py", line 442, in execute
    response = self.command_executor.execute(driver_command, params)
               ^^^^^^^^^^^^^^^^^^^^^^^^^^^^^^^^^^^^^^^^^^^^^^^^^^^^^
  File "C:\Users\pwst\AppData\Local\Programs\Python\Python311\Lib\site-packages\selenium\webdriver\remote\remote_connection.py", line 294, in execute
    return self._request(command_info[0], url, body=data)
           ^^^^^^^^^^^^^^^^^^^^^^^^^^^^^^^^^^^^^^^^^^^^^^
  File "C:\Users\pwst\AppData\Local\Programs\Python\Python311\Lib\site-packages\selenium\webdriver\remote\remote_connection.py", line 316, in _request
    response = self._conn.request(method, url, body=body, headers=headers)
               ^^^^^^^^^^^^^^^^^^^^^^^^^^^^^^^^^^^^^^^^^^^^^^^^^^^^^^^^^^^
  File "C:\Users\pwst\AppData\Local\Programs\Python\Python311\Lib\site-packages\urllib3\request.py", line 74, in request
    return self.request_encode_url(
           ^^^^^^^^^^^^^^^^^^^^^^^^
  File "C:\Users\pwst\AppData\Local\Programs\Python\Python311\Lib\site-packages\urllib3\request.py", line 96, in request_encode_url
    return self.urlopen(method, url, **extra_kw)
           ^^^^^^^^^^^^^^^^^^^^^^^^^^^^^^^^^^^^^
  File "C:\Users\pwst\AppData\Local\Programs\Python\Python311\Lib\site-packages\urllib3\poolmanager.py", line 376, in urlopen
    response = conn.urlopen(method, u.request_uri, **kw)
               ^^^^^^^^^^^^^^^^^^^^^^^^^^^^^^^^^^^^^^^^^
  File "C:\Users\pwst\AppData\Local\Programs\Python\Python311\Lib\site-packages\urllib3\connectionpool.py", line 815, in urlopen
    return self.urlopen(
           ^^^^^^^^^^^^^
  File "C:\Users\pwst\AppData\Local\Programs\Python\Python311\Lib\site-packages\urllib3\connectionpool.py", line 815, in urlopen
    return self.urlopen(
           ^^^^^^^^^^^^^
  File "C:\Users\pwst\AppData\Local\Programs\Python\Python311\Lib\site-packages\urllib3\connectionpool.py", line 815, in urlopen
    return self.urlopen(
           ^^^^^^^^^^^^^
  File "C:\Users\pwst\AppData\Local\Programs\Python\Python311\Lib\site-packages\urllib3\connectionpool.py", line 787, in urlopen
    retries = retries.increment(
              ^^^^^^^^^^^^^^^^^^
  File "C:\Users\pwst\AppData\Local\Programs\Python\Python311\Lib\site-packages\urllib3\util\retry.py", line 592, in increment
    raise MaxRetryError(_pool, url, error or ResponseError(cause))
urllib3.exceptions.MaxRetryError: HTTPConnectionPool(host='localhost', port=53315): Max retries exceeded with url: /session/087d1ef2366c9ea12ffcc182873be34a/screenshot (Caused by NewConnectionError('&lt;urllib3.connection.HTTPConnection object at 0x000001BB6489CC90&gt;: Failed to establish a new connection: [WinError 10061] No se puede establecer una conexión ya que el equipo de destino denegó expresamente dicha conexión'))


    </pre>
    </div>
    </td>
    <td align="right">
        <a  href="../../../../img/20221226_12_42_54.png" target="_blank">
            <img src="../../../../img/20221226_12_42_54.png" height="200px" width="400px"/>
        </a>
    </td>
</tr>

<tr id='ft1_7' class='none'>
    <td class='errorCase' width='300px'><div class='testcase'>test_005: Eliminar el registro creado</div></td>
    <td colspan='5' align='left' width='600px'> <!--print 输出框位置-->
    <!--默认收起错误信息 -Findyou
    <button id='btn_ft1_7' type="button"  class="btn btn-primary btn-xs collapsed" data-toggle="collapse" data-target='#div_ft1_7'>Error</button>
    <div id='div_ft1_7' class="collapse">  -->
    <!-- 默认展开错误信息 -Findyou -->
    <button id='btn_ft1_7' type="button"  class="btn btn-primary btn-xs" data-toggle="collapse" data-target='#div_ft1_7'>Error</button>
    <div id='div_ft1_7' class="collapse in">
    <pre style="overflow-y:scroll; overflow-x:hidden;height:200px; width:600px; margin:auto; border:1px solid #e1e1e1;">
    
ft1_7: 2022-12-26 12:43:27,532 - root - ERROR - No se dió click al botón Refrescar, revise si el xpath sigue siendo el mismo, revise la accion anterior si el xpath es el correcto o el tiempo de la accion
2022-12-26 12:43:27,534 - root - INFO -  Captura: C:\xampp\htdocs\Versiones\automatizaciones\AutoPWST\02FDP\report\img  screen：20221226_12_43_27.png
Traceback (most recent call last):
  File "C:\Users\pwst\AppData\Local\Programs\Python\Python311\Lib\site-packages\urllib3\connection.py", line 174, in _new_conn
    conn = connection.create_connection(
           ^^^^^^^^^^^^^^^^^^^^^^^^^^^^^
  File "C:\Users\pwst\AppData\Local\Programs\Python\Python311\Lib\site-packages\urllib3\util\connection.py", line 95, in create_connection
    raise err
  File "C:\Users\pwst\AppData\Local\Programs\Python\Python311\Lib\site-packages\urllib3\util\connection.py", line 85, in create_connection
    sock.connect(sa)
ConnectionRefusedError: [WinError 10061] No se puede establecer una conexión ya que el equipo de destino denegó expresamente dicha conexión

During handling of the above exception, another exception occurred:

Traceback (most recent call last):
  File "C:\Users\pwst\AppData\Local\Programs\Python\Python311\Lib\site-packages\urllib3\connectionpool.py", line 703, in urlopen
    httplib_response = self._make_request(
                       ^^^^^^^^^^^^^^^^^^^
  File "C:\Users\pwst\AppData\Local\Programs\Python\Python311\Lib\site-packages\urllib3\connectionpool.py", line 398, in _make_request
    conn.request(method, url, **httplib_request_kw)
  File "C:\Users\pwst\AppData\Local\Programs\Python\Python311\Lib\site-packages\urllib3\connection.py", line 239, in request
    super(HTTPConnection, self).request(method, url, body=body, headers=headers)
  File "C:\Users\pwst\AppData\Local\Programs\Python\Python311\Lib\http\client.py", line 1282, in request
    self._send_request(method, url, body, headers, encode_chunked)
  File "C:\Users\pwst\AppData\Local\Programs\Python\Python311\Lib\http\client.py", line 1328, in _send_request
    self.endheaders(body, encode_chunked=encode_chunked)
  File "C:\Users\pwst\AppData\Local\Programs\Python\Python311\Lib\http\client.py", line 1277, in endheaders
    self._send_output(message_body, encode_chunked=encode_chunked)
  File "C:\Users\pwst\AppData\Local\Programs\Python\Python311\Lib\http\client.py", line 1037, in _send_output
    self.send(msg)
  File "C:\Users\pwst\AppData\Local\Programs\Python\Python311\Lib\http\client.py", line 975, in send
    self.connect()
  File "C:\Users\pwst\AppData\Local\Programs\Python\Python311\Lib\site-packages\urllib3\connection.py", line 205, in connect
    conn = self._new_conn()
           ^^^^^^^^^^^^^^^^
  File "C:\Users\pwst\AppData\Local\Programs\Python\Python311\Lib\site-packages\urllib3\connection.py", line 186, in _new_conn
    raise NewConnectionError(
urllib3.exceptions.NewConnectionError: &lt;urllib3.connection.HTTPConnection object at 0x000001BB647FA390&gt;: Failed to establish a new connection: [WinError 10061] No se puede establecer una conexión ya que el equipo de destino denegó expresamente dicha conexión

During handling of the above exception, another exception occurred:

Traceback (most recent call last):
  File "C:\xampp\htdocs\Versiones\automatizaciones\AutoPWST\02FDP\testCase\eliminarregistro.py", line 22, in eliminarregistro
    Refresca3 = self.wait.until(conditions.visibility((By.XPATH, Configuracion.btn_Refresca)))
                ^^^^^^^^^^^^^^^^^^^^^^^^^^^^^^^^^^^^^^^^^^^^^^^^^^^^^^^^^^^^^^^^^^^^^^^^^^^^^^
  File "C:\Users\pwst\AppData\Local\Programs\Python\Python311\Lib\site-packages\selenium\webdriver\support\wait.py", line 86, in until
    value = method(self._driver)
            ^^^^^^^^^^^^^^^^^^^^
  File "C:\Users\pwst\AppData\Local\Programs\Python\Python311\Lib\site-packages\selenium\webdriver\support\expected_conditions.py", line 125, in _predicate
    return _element_if_visible(driver.find_element(*locator))
                               ^^^^^^^^^^^^^^^^^^^^^^^^^^^^^
  File "C:\Users\pwst\AppData\Local\Programs\Python\Python311\Lib\site-packages\selenium\webdriver\remote\webdriver.py", line 861, in find_element
    return self.execute(Command.FIND_ELEMENT, {"using": by, "value": value})["value"]
           ^^^^^^^^^^^^^^^^^^^^^^^^^^^^^^^^^^^^^^^^^^^^^^^^^^^^^^^^^^^^^^^^^
  File "C:\Users\pwst\AppData\Local\Programs\Python\Python311\Lib\site-packages\selenium\webdriver\remote\webdriver.py", line 442, in execute
    response = self.command_executor.execute(driver_command, params)
               ^^^^^^^^^^^^^^^^^^^^^^^^^^^^^^^^^^^^^^^^^^^^^^^^^^^^^
  File "C:\Users\pwst\AppData\Local\Programs\Python\Python311\Lib\site-packages\selenium\webdriver\remote\remote_connection.py", line 294, in execute
    return self._request(command_info[0], url, body=data)
           ^^^^^^^^^^^^^^^^^^^^^^^^^^^^^^^^^^^^^^^^^^^^^^
  File "C:\Users\pwst\AppData\Local\Programs\Python\Python311\Lib\site-packages\selenium\webdriver\remote\remote_connection.py", line 316, in _request
    response = self._conn.request(method, url, body=body, headers=headers)
               ^^^^^^^^^^^^^^^^^^^^^^^^^^^^^^^^^^^^^^^^^^^^^^^^^^^^^^^^^^^
  File "C:\Users\pwst\AppData\Local\Programs\Python\Python311\Lib\site-packages\urllib3\request.py", line 78, in request
    return self.request_encode_body(
           ^^^^^^^^^^^^^^^^^^^^^^^^^
  File "C:\Users\pwst\AppData\Local\Programs\Python\Python311\Lib\site-packages\urllib3\request.py", line 170, in request_encode_body
    return self.urlopen(method, url, **extra_kw)
           ^^^^^^^^^^^^^^^^^^^^^^^^^^^^^^^^^^^^^
  File "C:\Users\pwst\AppData\Local\Programs\Python\Python311\Lib\site-packages\urllib3\poolmanager.py", line 376, in urlopen
    response = conn.urlopen(method, u.request_uri, **kw)
               ^^^^^^^^^^^^^^^^^^^^^^^^^^^^^^^^^^^^^^^^^
  File "C:\Users\pwst\AppData\Local\Programs\Python\Python311\Lib\site-packages\urllib3\connectionpool.py", line 815, in urlopen
    return self.urlopen(
           ^^^^^^^^^^^^^
  File "C:\Users\pwst\AppData\Local\Programs\Python\Python311\Lib\site-packages\urllib3\connectionpool.py", line 815, in urlopen
    return self.urlopen(
           ^^^^^^^^^^^^^
  File "C:\Users\pwst\AppData\Local\Programs\Python\Python311\Lib\site-packages\urllib3\connectionpool.py", line 815, in urlopen
    return self.urlopen(
           ^^^^^^^^^^^^^
  File "C:\Users\pwst\AppData\Local\Programs\Python\Python311\Lib\site-packages\urllib3\connectionpool.py", line 787, in urlopen
    retries = retries.increment(
              ^^^^^^^^^^^^^^^^^^
  File "C:\Users\pwst\AppData\Local\Programs\Python\Python311\Lib\site-packages\urllib3\util\retry.py", line 592, in increment
    raise MaxRetryError(_pool, url, error or ResponseError(cause))
urllib3.exceptions.MaxRetryError: HTTPConnectionPool(host='localhost', port=53315): Max retries exceeded with url: /session/087d1ef2366c9ea12ffcc182873be34a/element (Caused by NewConnectionError('&lt;urllib3.connection.HTTPConnection object at 0x000001BB647FA390&gt;: Failed to establish a new connection: [WinError 10061] No se puede establecer una conexión ya que el equipo de destino denegó expresamente dicha conexión'))

During handling of the above exception, another exception occurred:

Traceback (most recent call last):
  File "C:\Users\pwst\AppData\Local\Programs\Python\Python311\Lib\site-packages\urllib3\connection.py", line 174, in _new_conn
    conn = connection.create_connection(
           ^^^^^^^^^^^^^^^^^^^^^^^^^^^^^
  File "C:\Users\pwst\AppData\Local\Programs\Python\Python311\Lib\site-packages\urllib3\util\connection.py", line 95, in create_connection
    raise err
  File "C:\Users\pwst\AppData\Local\Programs\Python\Python311\Lib\site-packages\urllib3\util\connection.py", line 85, in create_connection
    sock.connect(sa)
ConnectionRefusedError: [WinError 10061] No se puede establecer una conexión ya que el equipo de destino denegó expresamente dicha conexión

During handling of the above exception, another exception occurred:

Traceback (most recent call last):
  File "C:\Users\pwst\AppData\Local\Programs\Python\Python311\Lib\site-packages\urllib3\connectionpool.py", line 703, in urlopen
    httplib_response = self._make_request(
                       ^^^^^^^^^^^^^^^^^^^
  File "C:\Users\pwst\AppData\Local\Programs\Python\Python311\Lib\site-packages\urllib3\connectionpool.py", line 398, in _make_request
    conn.request(method, url, **httplib_request_kw)
  File "C:\Users\pwst\AppData\Local\Programs\Python\Python311\Lib\site-packages\urllib3\connection.py", line 239, in request
    super(HTTPConnection, self).request(method, url, body=body, headers=headers)
  File "C:\Users\pwst\AppData\Local\Programs\Python\Python311\Lib\http\client.py", line 1282, in request
    self._send_request(method, url, body, headers, encode_chunked)
  File "C:\Users\pwst\AppData\Local\Programs\Python\Python311\Lib\http\client.py", line 1328, in _send_request
    self.endheaders(body, encode_chunked=encode_chunked)
  File "C:\Users\pwst\AppData\Local\Programs\Python\Python311\Lib\http\client.py", line 1277, in endheaders
    self._send_output(message_body, encode_chunked=encode_chunked)
  File "C:\Users\pwst\AppData\Local\Programs\Python\Python311\Lib\http\client.py", line 1037, in _send_output
    self.send(msg)
  File "C:\Users\pwst\AppData\Local\Programs\Python\Python311\Lib\http\client.py", line 975, in send
    self.connect()
  File "C:\Users\pwst\AppData\Local\Programs\Python\Python311\Lib\site-packages\urllib3\connection.py", line 205, in connect
    conn = self._new_conn()
           ^^^^^^^^^^^^^^^^
  File "C:\Users\pwst\AppData\Local\Programs\Python\Python311\Lib\site-packages\urllib3\connection.py", line 186, in _new_conn
    raise NewConnectionError(
urllib3.exceptions.NewConnectionError: &lt;urllib3.connection.HTTPConnection object at 0x000001BB6489F0D0&gt;: Failed to establish a new connection: [WinError 10061] No se puede establecer una conexión ya que el equipo de destino denegó expresamente dicha conexión

During handling of the above exception, another exception occurred:

Traceback (most recent call last):
  File "C:\xampp\htdocs\Versiones\automatizaciones\AutoPWST\02FDP\testCase\formasdepago.py", line 130, in test_005
    success = eliminarregistro.eliminarregistro.eliminarregistro(self, conditions, Configuracion)
              ^^^^^^^^^^^^^^^^^^^^^^^^^^^^^^^^^^^^^^^^^^^^^^^^^^^^^^^^^^^^^^^^^^^^^^^^^^^^^^^^^^^
  File "C:\xampp\htdocs\Versiones\automatizaciones\AutoPWST\02FDP\testCase\eliminarregistro.py", line 32, in eliminarregistro
    self.driver.get_screenshot_as_file(img_name)
  File "C:\Users\pwst\AppData\Local\Programs\Python\Python311\Lib\site-packages\selenium\webdriver\remote\webdriver.py", line 929, in get_screenshot_as_file
    png = self.get_screenshot_as_png()
          ^^^^^^^^^^^^^^^^^^^^^^^^^^^^
  File "C:\Users\pwst\AppData\Local\Programs\Python\Python311\Lib\site-packages\selenium\webdriver\remote\webdriver.py", line 965, in get_screenshot_as_png
    return b64decode(self.get_screenshot_as_base64().encode("ascii"))
                     ^^^^^^^^^^^^^^^^^^^^^^^^^^^^^^^
  File "C:\Users\pwst\AppData\Local\Programs\Python\Python311\Lib\site-packages\selenium\webdriver\remote\webdriver.py", line 977, in get_screenshot_as_base64
    return self.execute(Command.SCREENSHOT)["value"]
           ^^^^^^^^^^^^^^^^^^^^^^^^^^^^^^^^
  File "C:\Users\pwst\AppData\Local\Programs\Python\Python311\Lib\site-packages\selenium\webdriver\remote\webdriver.py", line 442, in execute
    response = self.command_executor.execute(driver_command, params)
               ^^^^^^^^^^^^^^^^^^^^^^^^^^^^^^^^^^^^^^^^^^^^^^^^^^^^^
  File "C:\Users\pwst\AppData\Local\Programs\Python\Python311\Lib\site-packages\selenium\webdriver\remote\remote_connection.py", line 294, in execute
    return self._request(command_info[0], url, body=data)
           ^^^^^^^^^^^^^^^^^^^^^^^^^^^^^^^^^^^^^^^^^^^^^^
  File "C:\Users\pwst\AppData\Local\Programs\Python\Python311\Lib\site-packages\selenium\webdriver\remote\remote_connection.py", line 316, in _request
    response = self._conn.request(method, url, body=body, headers=headers)
               ^^^^^^^^^^^^^^^^^^^^^^^^^^^^^^^^^^^^^^^^^^^^^^^^^^^^^^^^^^^
  File "C:\Users\pwst\AppData\Local\Programs\Python\Python311\Lib\site-packages\urllib3\request.py", line 74, in request
    return self.request_encode_url(
           ^^^^^^^^^^^^^^^^^^^^^^^^
  File "C:\Users\pwst\AppData\Local\Programs\Python\Python311\Lib\site-packages\urllib3\request.py", line 96, in request_encode_url
    return self.urlopen(method, url, **extra_kw)
           ^^^^^^^^^^^^^^^^^^^^^^^^^^^^^^^^^^^^^
  File "C:\Users\pwst\AppData\Local\Programs\Python\Python311\Lib\site-packages\urllib3\poolmanager.py", line 376, in urlopen
    response = conn.urlopen(method, u.request_uri, **kw)
               ^^^^^^^^^^^^^^^^^^^^^^^^^^^^^^^^^^^^^^^^^
  File "C:\Users\pwst\AppData\Local\Programs\Python\Python311\Lib\site-packages\urllib3\connectionpool.py", line 815, in urlopen
    return self.urlopen(
           ^^^^^^^^^^^^^
  File "C:\Users\pwst\AppData\Local\Programs\Python\Python311\Lib\site-packages\urllib3\connectionpool.py", line 815, in urlopen
    return self.urlopen(
           ^^^^^^^^^^^^^
  File "C:\Users\pwst\AppData\Local\Programs\Python\Python311\Lib\site-packages\urllib3\connectionpool.py", line 815, in urlopen
    return self.urlopen(
           ^^^^^^^^^^^^^
  File "C:\Users\pwst\AppData\Local\Programs\Python\Python311\Lib\site-packages\urllib3\connectionpool.py", line 787, in urlopen
    retries = retries.increment(
              ^^^^^^^^^^^^^^^^^^
  File "C:\Users\pwst\AppData\Local\Programs\Python\Python311\Lib\site-packages\urllib3\util\retry.py", line 592, in increment
    raise MaxRetryError(_pool, url, error or ResponseError(cause))
urllib3.exceptions.MaxRetryError: HTTPConnectionPool(host='localhost', port=53315): Max retries exceeded with url: /session/087d1ef2366c9ea12ffcc182873be34a/screenshot (Caused by NewConnectionError('&lt;urllib3.connection.HTTPConnection object at 0x000001BB6489F0D0&gt;: Failed to establish a new connection: [WinError 10061] No se puede establecer una conexión ya que el equipo de destino denegó expresamente dicha conexión'))


    </pre>
    </div>
    </td>
    <td align="right">
        <a  href="../../../../img/20221226_12_43_27.png" target="_blank">
            <img src="../../../../img/20221226_12_43_27.png" height="200px" width="400px"/>
        </a>
    </td>
</tr>

<tr id='ft1_8' class='none'>
    <td class='errorCase' width='300px'><div class='testcase'>test_006: Cerrar_Navegador</div></td>
    <td colspan='5' align='left' width='600px'> <!--print 输出框位置-->
    <!--默认收起错误信息 -Findyou
    <button id='btn_ft1_8' type="button"  class="btn btn-primary btn-xs collapsed" data-toggle="collapse" data-target='#div_ft1_8'>Error</button>
    <div id='div_ft1_8' class="collapse">  -->
    <!-- 默认展开错误信息 -Findyou -->
    <button id='btn_ft1_8' type="button"  class="btn btn-primary btn-xs" data-toggle="collapse" data-target='#div_ft1_8'>Error</button>
    <div id='div_ft1_8' class="collapse in">
    <pre style="overflow-y:scroll; overflow-x:hidden;height:200px; width:600px; margin:auto; border:1px solid #e1e1e1;">
    
ft1_8: Traceback (most recent call last):
  File "C:\Users\pwst\AppData\Local\Programs\Python\Python311\Lib\site-packages\urllib3\connection.py", line 174, in _new_conn
    conn = connection.create_connection(
           ^^^^^^^^^^^^^^^^^^^^^^^^^^^^^
  File "C:\Users\pwst\AppData\Local\Programs\Python\Python311\Lib\site-packages\urllib3\util\connection.py", line 95, in create_connection
    raise err
  File "C:\Users\pwst\AppData\Local\Programs\Python\Python311\Lib\site-packages\urllib3\util\connection.py", line 85, in create_connection
    sock.connect(sa)
ConnectionRefusedError: [WinError 10061] No se puede establecer una conexión ya que el equipo de destino denegó expresamente dicha conexión

During handling of the above exception, another exception occurred:

Traceback (most recent call last):
  File "C:\Users\pwst\AppData\Local\Programs\Python\Python311\Lib\site-packages\urllib3\connectionpool.py", line 703, in urlopen
    httplib_response = self._make_request(
                       ^^^^^^^^^^^^^^^^^^^
  File "C:\Users\pwst\AppData\Local\Programs\Python\Python311\Lib\site-packages\urllib3\connectionpool.py", line 398, in _make_request
    conn.request(method, url, **httplib_request_kw)
  File "C:\Users\pwst\AppData\Local\Programs\Python\Python311\Lib\site-packages\urllib3\connection.py", line 239, in request
    super(HTTPConnection, self).request(method, url, body=body, headers=headers)
  File "C:\Users\pwst\AppData\Local\Programs\Python\Python311\Lib\http\client.py", line 1282, in request
    self._send_request(method, url, body, headers, encode_chunked)
  File "C:\Users\pwst\AppData\Local\Programs\Python\Python311\Lib\http\client.py", line 1328, in _send_request
    self.endheaders(body, encode_chunked=encode_chunked)
  File "C:\Users\pwst\AppData\Local\Programs\Python\Python311\Lib\http\client.py", line 1277, in endheaders
    self._send_output(message_body, encode_chunked=encode_chunked)
  File "C:\Users\pwst\AppData\Local\Programs\Python\Python311\Lib\http\client.py", line 1037, in _send_output
    self.send(msg)
  File "C:\Users\pwst\AppData\Local\Programs\Python\Python311\Lib\http\client.py", line 975, in send
    self.connect()
  File "C:\Users\pwst\AppData\Local\Programs\Python\Python311\Lib\site-packages\urllib3\connection.py", line 205, in connect
    conn = self._new_conn()
           ^^^^^^^^^^^^^^^^
  File "C:\Users\pwst\AppData\Local\Programs\Python\Python311\Lib\site-packages\urllib3\connection.py", line 186, in _new_conn
    raise NewConnectionError(
urllib3.exceptions.NewConnectionError: &lt;urllib3.connection.HTTPConnection object at 0x000001BB648B2090&gt;: Failed to establish a new connection: [WinError 10061] No se puede establecer una conexión ya que el equipo de destino denegó expresamente dicha conexión

During handling of the above exception, another exception occurred:

Traceback (most recent call last):
  File "C:\xampp\htdocs\Versiones\automatizaciones\AutoPWST\02FDP\testCase\formasdepago.py", line 148, in test_006
    self.driver.close()
  File "C:\Users\pwst\AppData\Local\Programs\Python\Python311\Lib\site-packages\selenium\webdriver\remote\webdriver.py", line 561, in close
    self.execute(Command.CLOSE)
  File "C:\Users\pwst\AppData\Local\Programs\Python\Python311\Lib\site-packages\selenium\webdriver\remote\webdriver.py", line 442, in execute
    response = self.command_executor.execute(driver_command, params)
               ^^^^^^^^^^^^^^^^^^^^^^^^^^^^^^^^^^^^^^^^^^^^^^^^^^^^^
  File "C:\Users\pwst\AppData\Local\Programs\Python\Python311\Lib\site-packages\selenium\webdriver\remote\remote_connection.py", line 294, in execute
    return self._request(command_info[0], url, body=data)
           ^^^^^^^^^^^^^^^^^^^^^^^^^^^^^^^^^^^^^^^^^^^^^^
  File "C:\Users\pwst\AppData\Local\Programs\Python\Python311\Lib\site-packages\selenium\webdriver\remote\remote_connection.py", line 316, in _request
    response = self._conn.request(method, url, body=body, headers=headers)
               ^^^^^^^^^^^^^^^^^^^^^^^^^^^^^^^^^^^^^^^^^^^^^^^^^^^^^^^^^^^
  File "C:\Users\pwst\AppData\Local\Programs\Python\Python311\Lib\site-packages\urllib3\request.py", line 74, in request
    return self.request_encode_url(
           ^^^^^^^^^^^^^^^^^^^^^^^^
  File "C:\Users\pwst\AppData\Local\Programs\Python\Python311\Lib\site-packages\urllib3\request.py", line 96, in request_encode_url
    return self.urlopen(method, url, **extra_kw)
           ^^^^^^^^^^^^^^^^^^^^^^^^^^^^^^^^^^^^^
  File "C:\Users\pwst\AppData\Local\Programs\Python\Python311\Lib\site-packages\urllib3\poolmanager.py", line 376, in urlopen
    response = conn.urlopen(method, u.request_uri, **kw)
               ^^^^^^^^^^^^^^^^^^^^^^^^^^^^^^^^^^^^^^^^^
  File "C:\Users\pwst\AppData\Local\Programs\Python\Python311\Lib\site-packages\urllib3\connectionpool.py", line 815, in urlopen
    return self.urlopen(
           ^^^^^^^^^^^^^
  File "C:\Users\pwst\AppData\Local\Programs\Python\Python311\Lib\site-packages\urllib3\connectionpool.py", line 815, in urlopen
    return self.urlopen(
           ^^^^^^^^^^^^^
  File "C:\Users\pwst\AppData\Local\Programs\Python\Python311\Lib\site-packages\urllib3\connectionpool.py", line 815, in urlopen
    return self.urlopen(
           ^^^^^^^^^^^^^
  File "C:\Users\pwst\AppData\Local\Programs\Python\Python311\Lib\site-packages\urllib3\connectionpool.py", line 787, in urlopen
    retries = retries.increment(
              ^^^^^^^^^^^^^^^^^^
  File "C:\Users\pwst\AppData\Local\Programs\Python\Python311\Lib\site-packages\urllib3\util\retry.py", line 592, in increment
    raise MaxRetryError(_pool, url, error or ResponseError(cause))
urllib3.exceptions.MaxRetryError: HTTPConnectionPool(host='localhost', port=53315): Max retries exceeded with url: /session/087d1ef2366c9ea12ffcc182873be34a/window (Caused by NewConnectionError('&lt;urllib3.connection.HTTPConnection object at 0x000001BB648B2090&gt;: Failed to establish a new connection: [WinError 10061] No se puede establecer una conexión ya que el equipo de destino denegó expresamente dicha conexión'))


    </pre>
    </div>
    </td>
    <td align="right">
        <a hidden="hidden" href="" target="_blank">
            <img src="" height="200px" width="400px"/>
        </a>
    </td>
</tr>

<tr id='total_row' class="text-center active">
    <td>Caso de prueba</td>
    <td>8</td>
    <td>0</td>
    <td>0</td>
    <td>8</td>
    <td>Taza de resultado：0.00%</td>
    <td> <a href="" target="_blank"></a></td>
</tr>
</table>

<div id='ending'> </div>
    <div style=" position:fixed;right:50px; bottom:30px; width:20px; height:20px;cursor:pointer">
    <a href="#"><span class="glyphicon glyphicon-eject" style = "font-size:30px;" aria-hidden="true">
    </span></a></div>
    
</body>
</html>
